Workbook

Sheet لوحة التحكم
A1: سجل متابعة الطلبة – الفصل الدراسي الأول 2026–2027
A2: نسخة مخصصة للفصل الدراسي الأول فقط • سبتمبر – أكتوبر – نوفمبر – ديسمبر 2026
A4: =HYPERLINK("#'لوحة الشعب'!A1","لوحة الشعب") -> لوحة الشعب | C4: =HYPERLINK("#'إعداد الشعب'!A1","إعداد الشعب") -> إعداد الشعب | E4: =HYPERLINK("#'الإعدادات'!A1","الإعدادات") -> الإعدادات | G4: =HYPERLINK("#'دليل الاستخدام'!A1","دليل الاستخدام") -> دليل الاستخدام
A6: المدرسة | C6: المادة الافتراضية | E6: المعلم الافتراضي | G6: العام الأكاديمي
A7: =الإعدادات!B5 -> اسم المدرسة | C7: =الإعدادات!B6 -> اسم المادة | E7: =الإعدادات!B7 -> اسم المعلم | G7: =الإعدادات!B4 -> 2026-2027
A9: الشعب المفعلة | C9: إجمالي الطلاب | E9: الملاحظات | G9: الغياب | I9: النوم | K9: حل الواجبات
A10: ='لوحة الشعب'!A6 -> 6 | C10: ='لوحة الشعب'!C6 -> 0 | E10: ='لوحة الشعب'!E6 -> 9 | G10: ='لوحة الشعب'!G6 -> 0 | I10: ='لوحة الشعب'!I6 -> 0 | K10: ='لوحة الشعب'!Q6 -> 0
A14: أشهر المتابعة في الفصل الدراسي الأول
A15: سبتمبر 2026 | C15: أكتوبر 2026 | E15: نوفمبر 2026 | G15: ديسمبر 2026
A19: طريقة البدء: افتح «إعداد الشعب» وفعّل الصفحات المطلوبة، ثم حدّد المرحلة والصف والشعبة والمادة والمعلم. بعد ذلك افتح صفحة الشعبة وأدخل أسماء الطلاب، ثم سجّل المتابعة اليومية في أشهر سبتمبر إلى ديسمبر.

Sheet الإعدادات
A1: =HYPERLINK("#'لوحة التحكم'!A1","⌂ إعدادات سجل متابعة الطلبة – الفصل الدراسي الأول 2026–2027") -> ⌂ إعدادات سجل متابعة الطلبة – الفصل الدراسي الأول 2026–2027
H2: خيارات التقييم – يمكن تعديل الأسماء بحرية
A3: البيان | B3: القيمة | D3: الصفوف | E3: الشعب | F3: المراحل | H3: اسم الخيار | I3: الاستخدام المقترح | J3: التصنيف
A4: العام الأكاديمي | B4: 2026-2027 | D4: 1 | E4: 1 | F4: ابتدائية | H4: كتاب | I4: عدم إحضار الكتاب/المستلزمات | J4: ملاحظة
A5: اسم المدرسة | B5: اسم المدرسة | D5: 2 | E5: 2 | F5: إعدادية | H5: نوم | I5: نوم أثناء الحصة | J5: ملاحظة
A6: المادة الدراسية | B6: اسم المادة | D6: 3 | E6: 3 | F6: ثانوية | H6: سلوك | I6: ملاحظة سلوكية | J6: ملاحظة
A7: اسم المعلم | B7: اسم المعلم | D7: 4 | E7: 4 | F7: أخرى | H7: غياب | I7: غياب الطالب | J7: ملاحظة
A8: عدد الطلاب المجهز لكل شعبة | B8: 40 | D8: 5 | E8: 5 | H8: تأخر | I8: تأخر الطالب | J8: ملاحظة
A9: الفصل الدراسي | B9: الأول | D9: 6 | E9: 6 | H9: حل الواجبات | I9: متابعة حل الواجبات | J9: متابعة إيجابية
D10: 7 | E10: 7 | H10: تميز ★ | I10: مشاركة أو أداء مميز | J10: إيجابي
D11: 8 | E11: 8
D12: 9 | E12: 9
D13: 10 | E13: 10
D14: 11
D15: 12
A16: مرجع التقويم السنوي | B16: https://edu.gov.qa/ar/Content/AnnualCalendar
A17: تفاصيل مواعيد 2026–2027 | B17: https://alarab.qa/article/24/08/2026/التعليم-تعلن-التقويم-السنوي-للمدارس-2026-2027
A18: هذه النسخة مخصصة للفصل الدراسي الأول 2026–2027، وتغطي سبتمبر وأكتوبر ونوفمبر وديسمبر 2026. تم استبعاد إجازة منتصف الفصل من 25 إلى 29 أكتوبر، وتنتهي متابعة ديسمبر قبل إجازة منتصف العام.

Sheet دليل الاستخدام
A1: دليل استخدام السجل – الفصل الدراسي الأول
A3: الخطوة | B3: الإجراء | C3: المكان | D3: النتيجة | E3: ملاحظة
A4: 1 | B4: عدّل اسم المدرسة والمادة والمعلم وخيارات التقييم. | C4: الإعدادات | D4: تتحدث البيانات تلقائيًا. | E4: الخيار المعتمد في المتابعة هو «نوم».
A5: 2 | B5: فعّل صفحة الشعبة وحدد المرحلة والصف والشعبة والمادة والمعلم. | C5: إعداد الشعب | D5: تُخصص الصفحة للشعبة المطلوبة. | E5: يدعم الصفوف 1–12 والشعب 1–10.
A6: 3 | B6: افتح صفحة الشعبة من لوحة الشعب. | C6: لوحة الشعب | D6: انتقال مباشر إلى سجل الشعبة. | E6: كل شعبة مستقلة عن الأخرى.
A7: 4 | B7: أدخل أسماء الطلاب وحدد «نشط؟ = نعم». | C7: صفحة الشعبة | D7: تظهر الأسماء تلقائيًا في الأشهر الستة. | E7: حتى 40 طالبًا لكل شعبة.
A8: 5 | B8: سجّل المتابعة اليومية. | C8: سبتمبر–ديسمبر 2026 | D8: تُحسب الملخصات تلقائيًا. | E8: كتاب، نوم، سلوك، غياب، تأخر، حل الواجبات، تميز ★.
A9: 6 | B9: اختر طالبًا في التقرير السريع. | C9: أعلى صفحة الشعبة | D9: تظهر إحصاءاته في الأشهر الستة. | E9: يشمل إجمالي الفصل الدراسي الأول.
A10: الفصل الأول | B10: المتابعة من سبتمبر إلى ديسمبر 2026. | C10: إجازة أكتوبر | D10: لا تظهر أيام 25–29 أكتوبر في المتابعة. | E10: إجازة منتصف العام تبدأ 20 ديسمبر 2026.

Sheet إعداد الشعب
A1: إعداد الشعب – كل صف يمثل صفحة شعبة مستقلة
A2: فعّل الصفحات التي تحتاجها فقط، ثم حدّد المرحلة والصف والشعبة والمادة والمعلم. كل صفحة تصلح لأي صف من 1 إلى 12.
A3: رقم | B3: فعال؟ | C3: المرحلة | D3: الصف | E3: الشعبة | F3: المادة | G3: المعلم | H3: الاسم المعروض | I3: فتح الصفحة | J3: ملاحظات
A4: 1 | B4: نعم | C4: إعدادية | D4: 7 | E4: 1 | F4: الحوسبة وتكنولوجيا المعلومات | G4: جمال صالح | H4: =IF(B4<>"نعم","",C4&" - الصف "&D4&" - شعبة "&E4&" - "&IF(F4="",الإعدادات!B6,F4)) -> إعدادية - الصف 7 - شعبة 1 - الحوسبة وتكنولوجيا المعلومات | I4: =HYPERLINK("#'شعبة 01'!A1",IF(B4="نعم","فتح","")) -> فتح
A5: 2 | B5: نعم | C5: إعدادية | D5: 7 | E5: 2 | F5: الحوسبة وتكنولوجيا المعلومات | G5: جمال صالح | H5: =IF(B5<>"نعم","",C5&" - الصف "&D5&" - شعبة "&E5&" - "&IF(F5="",الإعدادات!B6,F5)) -> إعدادية - الصف 7 - شعبة 2 - الحوسبة وتكنولوجيا المعلومات | I5: =HYPERLINK("#'شعبة 02'!A1",IF(B5="نعم","فتح","")) -> فتح
A6: 3 | B6: نعم | C6: إعدادية | D6: 7 | E6: 3 | F6: الحوسبة وتكنولوجيا المعلومات | G6: جمال صالح | H6: =IF(B6<>"نعم","",C6&" - الصف "&D6&" - شعبة "&E6&" - "&IF(F6="",الإعدادات!B6,F6)) -> إعدادية - الصف 7 - شعبة 3 - الحوسبة وتكنولوجيا المعلومات | I6: =HYPERLINK("#'شعبة 03'!A1",IF(B6="نعم","فتح","")) -> فتح
A7: 4 | B7: نعم | C7: إعدادية | D7: 7 | E7: 4 | F7: الحوسبة وتكنولوجيا المعلومات | G7: جمال صالح | H7: =IF(B7<>"نعم","",C7&" - الصف "&D7&" - شعبة "&E7&" - "&IF(F7="",الإعدادات!B6,F7)) -> إعدادية - الصف 7 - شعبة 4 - الحوسبة وتكنولوجيا المعلومات | I7: =HYPERLINK("#'شعبة 04'!A1",IF(B7="نعم","فتح","")) -> فتح
A8: 5 | B8: نعم | C8: إعدادية | D8: 8 | E8: 1 | F8: الحوسبة وتكنولوجيا المعلومات | G8: جمال صالح | H8: =IF(B8<>"نعم","",C8&" - الصف "&D8&" - شعبة "&E8&" - "&IF(F8="",الإعدادات!B6,F8)) -> إعدادية - الصف 8 - شعبة 1 - الحوسبة وتكنولوجيا المعلومات | I8: =HYPERLINK("#'شعبة 05'!A1",IF(B8="نعم","فتح","")) -> فتح
A9: 6 | B9: نعم | C9: إعدادية | D9: 8 | E9: 2 | F9: الحوسبة وتكنولوجيا المعلومات | G9: جمال صالح | H9: =IF(B9<>"نعم","",C9&" - الصف "&D9&" - شعبة "&E9&" - "&IF(F9="",الإعدادات!B6,F9)) -> إعدادية - الصف 8 - شعبة 2 - الحوسبة وتكنولوجيا المعلومات | I9: =HYPERLINK("#'شعبة 06'!A1",IF(B9="نعم","فتح","")) -> فتح
A10: 7 | H10: =IF(B10<>"نعم","",C10&" - الصف "&D10&" - شعبة "&E10&" - "&IF(F10="",الإعدادات!B6,F10)) | I10: =HYPERLINK("#'شعبة 07'!A1",IF(B10="نعم","فتح",""))
A11: 8 | H11: =IF(B11<>"نعم","",C11&" - الصف "&D11&" - شعبة "&E11&" - "&IF(F11="",الإعدادات!B6,F11)) | I11: =HYPERLINK("#'شعبة 08'!A1",IF(B11="نعم","فتح",""))
A12: 9 | H12: =IF(B12<>"نعم","",C12&" - الصف "&D12&" - شعبة "&E12&" - "&IF(F12="",الإعدادات!B6,F12)) | I12: =HYPERLINK("#'شعبة 09'!A1",IF(B12="نعم","فتح",""))
A13: 10 | H13: =IF(B13<>"نعم","",C13&" - الصف "&D13&" - شعبة "&E13&" - "&IF(F13="",الإعدادات!B6,F13)) | I13: =HYPERLINK("#'شعبة 10'!A1",IF(B13="نعم","فتح",""))
A14: 11 | H14: =IF(B14<>"نعم","",C14&" - الصف "&D14&" - شعبة "&E14&" - "&IF(F14="",الإعدادات!B6,F14)) | I14: =HYPERLINK("#'شعبة 11'!A1",IF(B14="نعم","فتح",""))
A15: 12 | H15: =IF(B15<>"نعم","",C15&" - الصف "&D15&" - شعبة "&E15&" - "&IF(F15="",الإعدادات!B6,F15)) | I15: =HYPERLINK("#'شعبة 12'!A1",IF(B15="نعم","فتح",""))
A16: 13 | H16: =IF(B16<>"نعم","",C16&" - الصف "&D16&" - شعبة "&E16&" - "&IF(F16="",الإعدادات!B6,F16)) | I16: =HYPERLINK("#'شعبة 13'!A1",IF(B16="نعم","فتح",""))
A17: 14 | H17: =IF(B17<>"نعم","",C17&" - الصف "&D17&" - شعبة "&E17&" - "&IF(F17="",الإعدادات!B6,F17)) | I17: =HYPERLINK("#'شعبة 14'!A1",IF(B17="نعم","فتح",""))
A18: 15 | H18: =IF(B18<>"نعم","",C18&" - الصف "&D18&" - شعبة "&E18&" - "&IF(F18="",الإعدادات!B6,F18)) | I18: =HYPERLINK("#'شعبة 15'!A1",IF(B18="نعم","فتح",""))
A19: 16 | H19: =IF(B19<>"نعم","",C19&" - الصف "&D19&" - شعبة "&E19&" - "&IF(F19="",الإعدادات!B6,F19)) | I19: =HYPERLINK("#'شعبة 16'!A1",IF(B19="نعم","فتح",""))
A20: 17 | H20: =IF(B20<>"نعم","",C20&" - الصف "&D20&" - شعبة "&E20&" - "&IF(F20="",الإعدادات!B6,F20)) | I20: =HYPERLINK("#'شعبة 17'!A1",IF(B20="نعم","فتح",""))
A21: 18 | H21: =IF(B21<>"نعم","",C21&" - الصف "&D21&" - شعبة "&E21&" - "&IF(F21="",الإعدادات!B6,F21)) | I21: =HYPERLINK("#'شعبة 18'!A1",IF(B21="نعم","فتح",""))
A22: 19 | H22: =IF(B22<>"نعم","",C22&" - الصف "&D22&" - شعبة "&E22&" - "&IF(F22="",الإعدادات!B6,F22)) | I22: =HYPERLINK("#'شعبة 19'!A1",IF(B22="نعم","فتح",""))
A23: 20 | H23: =IF(B23<>"نعم","",C23&" - الصف "&D23&" - شعبة "&E23&" - "&IF(F23="",الإعدادات!B6,F23)) | I23: =HYPERLINK("#'شعبة 20'!A1",IF(B23="نعم","فتح",""))

Sheet لوحة الشعب
A1: لوحة الشعب – سجل متابعة الفصل الدراسي الأول 2026–2027
A2: الإعدادات | B2: إعداد الشعب | C2: لوحة التحكم | D2: العام الأكاديمي | P2: المؤشر | Q2: الإجمالي
A3: =HYPERLINK("#'الإعدادات'!A1","الإعدادات") -> الإعدادات | B3: =HYPERLINK("#'إعداد الشعب'!A1","إعداد الشعب") -> إعداد الشعب | C3: =HYPERLINK("#'لوحة التحكم'!A1","العودة للرئيسية") -> العودة للرئيسية | D3: =الإعدادات!B4 -> 2026-2027 | P3: مجموع الملاحظات | Q3: =SUM(I11:I30) -> 9
P4: الغياب | Q4: =SUM(J11:J30) -> 0
A5: الشعب المفعلة | C5: إجمالي الطلاب | E5: الملاحظات | G5: الغياب | I5: النوم | P5: النوم | Q5: =SUM(K11:K30) -> 0
A6: =COUNTIF('إعداد الشعب'!B4:B23,"نعم") -> 6 | C6: =SUM(H11:H30) -> 0 | E6: =SUM(I11:I30) -> 9 | G6: =SUM(J11:J30) -> 0 | I6: =SUM(K11:K30) -> 0 | P6: حل الواجبات | Q6: =SUM(L11:L30) -> 0
P7: تميز ★ | Q7: =SUM(M11:M30) -> 5
A8: الفصل الدراسي الأول: سبتمبر – أكتوبر – نوفمبر – ديسمبر 2026
A10: رقم | B10: الشعبة/المادة | C10: المرحلة | D10: الصف | E10: الشعبة | F10: المادة | G10: المعلم | H10: الطلاب | I10: الملاحظات | J10: الغياب | K10: النوم | L10: حل الواجبات | M10: تميز | N10: فتح
A11: =1 -> 1 | B11: =IF('إعداد الشعب'!B4<>"نعم","",'إعداد الشعب'!H4) -> إعدادية - الصف 7 - شعبة 1 - الحوسبة وتكنولوجيا المعلومات | C11: =IF('إعداد الشعب'!B4<>"نعم","",'إعداد الشعب'!C4) -> إعدادية | D11: =IF('إعداد الشعب'!B4<>"نعم","",'إعداد الشعب'!D4) -> 7 | E11: =IF('إعداد الشعب'!B4<>"نعم","",'إعداد الشعب'!E4) -> 1 | F11: =IF('إعداد الشعب'!B4<>"نعم","",IF('إعداد الشعب'!F4="",الإعدادات!B6,'إعداد الشعب'!F4)) -> الحوسبة وتكنولوجيا المعلومات | G11: =IF('إعداد الشعب'!B4<>"نعم","",IF('إعداد الشعب'!G4="",الإعدادات!B7,'إعداد الشعب'!G4)) -> جمال صالح | H11: =IF('إعداد الشعب'!B4<>"نعم","",'شعبة 01'!A5) -> 0 | I11: =IF('إعداد الشعب'!B4<>"نعم","",'شعبة 01'!C5) -> 0 | J11: =IF('إعداد الشعب'!B4<>"نعم","",'شعبة 01'!E5) -> 0 | K11: =IF('إعداد الشعب'!B4<>"نعم","",'شعبة 01'!G5) -> 0 | L11: =IF('إعداد الشعب'!B4<>"نعم","",'شعبة 01'!I5) -> 0 | M11: =IF('إعداد الشعب'!B4<>"نعم","",'شعبة 01'!K5) -> 0 | N11: =IF('إعداد الشعب'!B4<>"نعم","",HYPERLINK("#'شعبة 01'!A1","فتح")) -> فتح
A12: =2 -> 2 | B12: =IF('إعداد الشعب'!B5<>"نعم","",'إعداد الشعب'!H5) -> إعدادية - الصف 7 - شعبة 2 - الحوسبة وتكنولوجيا المعلومات | C12: =IF('إعداد الشعب'!B5<>"نعم","",'إعداد الشعب'!C5) -> إعدادية | D12: =IF('إعداد الشعب'!B5<>"نعم","",'إعداد الشعب'!D5) -> 7 | E12: =IF('إعداد الشعب'!B5<>"نعم","",'إعداد الشعب'!E5) -> 2 | F12: =IF('إعداد الشعب'!B5<>"نعم","",IF('إعداد الشعب'!F5="",الإعدادات!B6,'إعداد الشعب'!F5)) -> الحوسبة وتكنولوجيا المعلومات | G12: =IF('إعداد الشعب'!B5<>"نعم","",IF('إعداد الشعب'!G5="",الإعدادات!B7,'إعداد الشعب'!G5)) -> جمال صالح | H12: =IF('إعداد الشعب'!B5<>"نعم","",'شعبة 02'!A5) -> 0 | I12: =IF('إعداد الشعب'!B5<>"نعم","",'شعبة 02'!C5) -> 0 | J12: =IF('إعداد الشعب'!B5<>"نعم","",'شعبة 02'!E5) -> 0 | K12: =IF('إعداد الشعب'!B5<>"نعم","",'شعبة 02'!G5) -> 0 | L12: =IF('إعداد الشعب'!B5<>"نعم","",'شعبة 02'!I5) -> 0 | M12: =IF('إعداد الشعب'!B5<>"نعم","",'شعبة 02'!K5) -> 0 | N12: =IF('إعداد الشعب'!B5<>"نعم","",HYPERLINK("#'شعبة 02'!A1","فتح")) -> فتح
A13: =3 -> 3 | B13: =IF('إعداد الشعب'!B6<>"نعم","",'إعداد الشعب'!H6) -> إعدادية - الصف 7 - شعبة 3 - الحوسبة وتكنولوجيا المعلومات | C13: =IF('إعداد الشعب'!B6<>"نعم","",'إعداد الشعب'!C6) -> إعدادية | D13: =IF('إعداد الشعب'!B6<>"نعم","",'إعداد الشعب'!D6) -> 7 | E13: =IF('إعداد الشعب'!B6<>"نعم","",'إعداد الشعب'!E6) -> 3 | F13: =IF('إعداد الشعب'!B6<>"نعم","",IF('إعداد الشعب'!F6="",الإعدادات!B6,'إعداد الشعب'!F6)) -> الحوسبة وتكنولوجيا المعلومات | G13: =IF('إعداد الشعب'!B6<>"نعم","",IF('إعداد الشعب'!G6="",الإعدادات!B7,'إعداد الشعب'!G6)) -> جمال صالح | H13: =IF('إعداد الشعب'!B6<>"نعم","",'شعبة 03'!A5) -> 0 | I13: =IF('إعداد الشعب'!B6<>"نعم","",'شعبة 03'!C5) -> 0 | J13: =IF('إعداد الشعب'!B6<>"نعم","",'شعبة 03'!E5) -> 0 | K13: =IF('إعداد الشعب'!B6<>"نعم","",'شعبة 03'!G5) -> 0 | L13: =IF('إعداد الشعب'!B6<>"نعم","",'شعبة 03'!I5) -> 0 | M13: =IF('إعداد الشعب'!B6<>"نعم","",'شعبة 03'!K5) -> 0 | N13: =IF('إعداد الشعب'!B6<>"نعم","",HYPERLINK("#'شعبة 03'!A1","فتح")) -> فتح
A14: =4 -> 4 | B14: =IF('إعداد الشعب'!B7<>"نعم","",'إعداد الشعب'!H7) -> إعدادية - الصف 7 - شعبة 4 - الحوسبة وتكنولوجيا المعلومات | C14: =IF('إعداد الشعب'!B7<>"نعم","",'إعداد الشعب'!C7) -> إعدادية | D14: =IF('إعداد الشعب'!B7<>"نعم","",'إعداد الشعب'!D7) -> 7 | E14: =IF('إعداد الشعب'!B7<>"نعم","",'إعداد الشعب'!E7) -> 4 | F14: =IF('إعداد الشعب'!B7<>"نعم","",IF('إعداد الشعب'!F7="",الإعدادات!B6,'إعداد الشعب'!F7)) -> الحوسبة وتكنولوجيا المعلومات | G14: =IF('إعداد الشعب'!B7<>"نعم","",IF('إعداد الشعب'!G7="",الإعدادات!B7,'إعداد الشعب'!G7)) -> جمال صالح | H14: =IF('إعداد الشعب'!B7<>"نعم","",'شعبة 04'!A5) -> 0 | I14: =IF('إعداد الشعب'!B7<>"نعم","",'شعبة 04'!C5) -> 0 | J14: =IF('إعداد الشعب'!B7<>"نعم","",'شعبة 04'!E5) -> 0 | K14: =IF('إعداد الشعب'!B7<>"نعم","",'شعبة 04'!G5) -> 0 | L14: =IF('إعداد الشعب'!B7<>"نعم","",'شعبة 04'!I5) -> 0 | M14: =IF('إعداد الشعب'!B7<>"نعم","",'شعبة 04'!K5) -> 0 | N14: =IF('إعداد الشعب'!B7<>"نعم","",HYPERLINK("#'شعبة 04'!A1","فتح")) -> فتح
A15: =5 -> 5 | B15: =IF('إعداد الشعب'!B8<>"نعم","",'إعداد الشعب'!H8) -> إعدادية - الصف 8 - شعبة 1 - الحوسبة وتكنولوجيا المعلومات | C15: =IF('إعداد الشعب'!B8<>"نعم","",'إعداد الشعب'!C8) -> إعدادية | D15: =IF('إعداد الشعب'!B8<>"نعم","",'إعداد الشعب'!D8) -> 8 | E15: =IF('إعداد الشعب'!B8<>"نعم","",'إعداد الشعب'!E8) -> 1 | F15: =IF('إعداد الشعب'!B8<>"نعم","",IF('إعداد الشعب'!F8="",الإعدادات!B6,'إعداد الشعب'!F8)) -> الحوسبة وتكنولوجيا المعلومات | G15: =IF('إعداد الشعب'!B8<>"نعم","",IF('إعداد الشعب'!G8="",الإعدادات!B7,'إعداد الشعب'!G8)) -> جمال صالح | H15: =IF('إعداد الشعب'!B8<>"نعم","",'شعبة 05'!A5) -> 0 | I15: =IF('إعداد الشعب'!B8<>"نعم","",'شعبة 05'!C5) -> 0 | J15: =IF('إعداد الشعب'!B8<>"نعم","",'شعبة 05'!E5) -> 0 | K15: =IF('إعداد الشعب'!B8<>"نعم","",'شعبة 05'!G5) -> 0 | L15: =IF('إعداد الشعب'!B8<>"نعم","",'شعبة 05'!I5) -> 0 | M15: =IF('إعداد الشعب'!B8<>"نعم","",'شعبة 05'!K5) -> 0 | N15: =IF('إعداد الشعب'!B8<>"نعم","",HYPERLINK("#'شعبة 05'!A1","فتح")) -> فتح
A16: =6 -> 6 | B16: =IF('إعداد الشعب'!B9<>"نعم","",'إعداد الشعب'!H9) -> إعدادية - الصف 8 - شعبة 2 - الحوسبة وتكنولوجيا المعلومات | C16: =IF('إعداد الشعب'!B9<>"نعم","",'إعداد الشعب'!C9) -> إعدادية | D16: =IF('إعداد الشعب'!B9<>"نعم","",'إعداد الشعب'!D9) -> 8 | E16: =IF('إعداد الشعب'!B9<>"نعم","",'إعداد الشعب'!E9) -> 2 | F16: =IF('إعداد الشعب'!B9<>"نعم","",IF('إعداد الشعب'!F9="",الإعدادات!B6,'إعداد الشعب'!F9)) -> الحوسبة وتكنولوجيا المعلومات | G16: =IF('إعداد الشعب'!B9<>"نعم","",IF('إعداد الشعب'!G9="",الإعدادات!B7,'إعداد الشعب'!G9)) -> جمال صالح | H16: =IF('إعداد الشعب'!B9<>"نعم","",'شعبة 06'!A5) -> 0 | I16: =IF('إعداد الشعب'!B9<>"نعم","",'شعبة 06'!C5) -> 9 | J16: =IF('إعداد الشعب'!B9<>"نعم","",'شعبة 06'!E5) -> 0 | K16: =IF('إعداد الشعب'!B9<>"نعم","",'شعبة 06'!G5) -> 0 | L16: =IF('إعداد الشعب'!B9<>"نعم","",'شعبة 06'!I5) -> 0 | M16: =IF('إعداد الشعب'!B9<>"نعم","",'شعبة 06'!K5) -> 5 | N16: =IF('إعداد الشعب'!B9<>"نعم","",HYPERLINK("#'شعبة 06'!A1","فتح")) -> فتح
A17: =7 -> 7 | B17: =IF('إعداد الشعب'!B10<>"نعم","",'إعداد الشعب'!H10) | C17: =IF('إعداد الشعب'!B10<>"نعم","",'إعداد الشعب'!C10) | D17: =IF('إعداد الشعب'!B10<>"نعم","",'إعداد الشعب'!D10) | E17: =IF('إعداد الشعب'!B10<>"نعم","",'إعداد الشعب'!E10) | F17: =IF('إعداد الشعب'!B10<>"نعم","",IF('إعداد الشعب'!F10="",الإعدادات!B6,'إعداد الشعب'!F10)) | G17: =IF('إعداد الشعب'!B10<>"نعم","",IF('إعداد الشعب'!G10="",الإعدادات!B7,'إعداد الشعب'!G10)) | H17: =IF('إعداد الشعب'!B10<>"نعم","",'شعبة 07'!A5) | I17: =IF('إعداد الشعب'!B10<>"نعم","",'شعبة 07'!C5) | J17: =IF('إعداد الشعب'!B10<>"نعم","",'شعبة 07'!E5) | K17: =IF('إعداد الشعب'!B10<>"نعم","",'شعبة 07'!G5) | L17: =IF('إعداد الشعب'!B10<>"نعم","",'شعبة 07'!I5) | M17: =IF('إعداد الشعب'!B10<>"نعم","",'شعبة 07'!K5) | N17: =IF('إعداد الشعب'!B10<>"نعم","",HYPERLINK("#'شعبة 07'!A1","فتح"))
A18: =8 -> 8 | B18: =IF('إعداد الشعب'!B11<>"نعم","",'إعداد الشعب'!H11) | C18: =IF('إعداد الشعب'!B11<>"نعم","",'إعداد الشعب'!C11) | D18: =IF('إعداد الشعب'!B11<>"نعم","",'إعداد الشعب'!D11) | E18: =IF('إعداد الشعب'!B11<>"نعم","",'إعداد الشعب'!E11) | F18: =IF('إعداد الشعب'!B11<>"نعم","",IF('إعداد الشعب'!F11="",الإعدادات!B6,'إعداد الشعب'!F11)) | G18: =IF('إعداد الشعب'!B11<>"نعم","",IF('إعداد الشعب'!G11="",الإعدادات!B7,'إعداد الشعب'!G11)) | H18: =IF('إعداد الشعب'!B11<>"نعم","",'شعبة 08'!A5) | I18: =IF('إعداد الشعب'!B11<>"نعم","",'شعبة 08'!C5) | J18: =IF('إعداد الشعب'!B11<>"نعم","",'شعبة 08'!E5) | K18: =IF('إعداد الشعب'!B11<>"نعم","",'شعبة 08'!G5) | L18: =IF('إعداد الشعب'!B11<>"نعم","",'شعبة 08'!I5) | M18: =IF('إعداد الشعب'!B11<>"نعم","",'شعبة 08'!K5) | N18: =IF('إعداد الشعب'!B11<>"نعم","",HYPERLINK("#'شعبة 08'!A1","فتح"))
A19: =9 -> 9 | B19: =IF('إعداد الشعب'!B12<>"نعم","",'إعداد الشعب'!H12) | C19: =IF('إعداد الشعب'!B12<>"نعم","",'إعداد الشعب'!C12) | D19: =IF('إعداد الشعب'!B12<>"نعم","",'إعداد الشعب'!D12) | E19: =IF('إعداد الشعب'!B12<>"نعم","",'إعداد الشعب'!E12) | F19: =IF('إعداد الشعب'!B12<>"نعم","",IF('إعداد الشعب'!F12="",الإعدادات!B6,'إعداد الشعب'!F12)) | G19: =IF('إعداد الشعب'!B12<>"نعم","",IF('إعداد الشعب'!G12="",الإعدادات!B7,'إعداد الشعب'!G12)) | H19: =IF('إعداد الشعب'!B12<>"نعم","",'شعبة 09'!A5) | I19: =IF('إعداد الشعب'!B12<>"نعم","",'شعبة 09'!C5) | J19: =IF('إعداد الشعب'!B12<>"نعم","",'شعبة 09'!E5) | K19: =IF('إعداد الشعب'!B12<>"نعم","",'شعبة 09'!G5) | L19: =IF('إعداد الشعب'!B12<>"نعم","",'شعبة 09'!I5) | M19: =IF('إعداد الشعب'!B12<>"نعم","",'شعبة 09'!K5) | N19: =IF('إعداد الشعب'!B12<>"نعم","",HYPERLINK("#'شعبة 09'!A1","فتح"))
A20: =10 -> 10 | B20: =IF('إعداد الشعب'!B13<>"نعم","",'إعداد الشعب'!H13) | C20: =IF('إعداد الشعب'!B13<>"نعم","",'إعداد الشعب'!C13) | D20: =IF('إعداد الشعب'!B13<>"نعم","",'إعداد الشعب'!D13) | E20: =IF('إعداد الشعب'!B13<>"نعم","",'إعداد الشعب'!E13) | F20: =IF('إعداد الشعب'!B13<>"نعم","",IF('إعداد الشعب'!F13="",الإعدادات!B6,'إعداد الشعب'!F13)) | G20: =IF('إعداد الشعب'!B13<>"نعم","",IF('إعداد الشعب'!G13="",الإعدادات!B7,'إعداد الشعب'!G13)) | H20: =IF('إعداد الشعب'!B13<>"نعم","",'شعبة 10'!A5) | I20: =IF('إعداد الشعب'!B13<>"نعم","",'شعبة 10'!C5) | J20: =IF('إعداد الشعب'!B13<>"نعم","",'شعبة 10'!E5) | K20: =IF('إعداد الشعب'!B13<>"نعم","",'شعبة 10'!G5) | L20: =IF('إعداد الشعب'!B13<>"نعم","",'شعبة 10'!I5) | M20: =IF('إعداد الشعب'!B13<>"نعم","",'شعبة 10'!K5) | N20: =IF('إعداد الشعب'!B13<>"نعم","",HYPERLINK("#'شعبة 10'!A1","فتح"))
A21: =11 -> 11 | B21: =IF('إعداد الشعب'!B14<>"نعم","",'إعداد الشعب'!H14) | C21: =IF('إعداد الشعب'!B14<>"نعم","",'إعداد الشعب'!C14) | D21: =IF('إعداد الشعب'!B14<>"نعم","",'إعداد الشعب'!D14) | E21: =IF('إعداد الشعب'!B14<>"نعم","",'إعداد الشعب'!E14) | F21: =IF('إعداد الشعب'!B14<>"نعم","",IF('إعداد الشعب'!F14="",الإعدادات!B6,'إعداد الشعب'!F14)) | G21: =IF('إعداد الشعب'!B14<>"نعم","",IF('إعداد الشعب'!G14="",الإعدادات!B7,'إعداد الشعب'!G14)) | H21: =IF('إعداد الشعب'!B14<>"نعم","",'شعبة 11'!A5) | I21: =IF('إعداد الشعب'!B14<>"نعم","",'شعبة 11'!C5) | J21: =IF('إعداد الشعب'!B14<>"نعم","",'شعبة 11'!E5) | K21: =IF('إعداد الشعب'!B14<>"نعم","",'شعبة 11'!G5) | L21: =IF('إعداد الشعب'!B14<>"نعم","",'شعبة 11'!I5) | M21: =IF('إعداد الشعب'!B14<>"نعم","",'شعبة 11'!K5) | N21: =IF('إعداد الشعب'!B14<>"نعم","",HYPERLINK("#'شعبة 11'!A1","فتح"))
A22: =12 -> 12 | B22: =IF('إعداد الشعب'!B15<>"نعم","",'إعداد الشعب'!H15) | C22: =IF('إعداد الشعب'!B15<>"نعم","",'إعداد الشعب'!C15) | D22: =IF('إعداد الشعب'!B15<>"نعم","",'إعداد الشعب'!D15) | E22: =IF('إعداد الشعب'!B15<>"نعم","",'إعداد الشعب'!E15) | F22: =IF('إعداد الشعب'!B15<>"نعم","",IF('إعداد الشعب'!F15="",الإعدادات!B6,'إعداد الشعب'!F15)) | G22: =IF('إعداد الشعب'!B15<>"نعم","",IF('إعداد الشعب'!G15="",الإعدادات!B7,'إعداد الشعب'!G15)) | H22: =IF('إعداد الشعب'!B15<>"نعم","",'شعبة 12'!A5) | I22: =IF('إعداد الشعب'!B15<>"نعم","",'شعبة 12'!C5) | J22: =IF('إعداد الشعب'!B15<>"نعم","",'شعبة 12'!E5) | K22: =IF('إعداد الشعب'!B15<>"نعم","",'شعبة 12'!G5) | L22: =IF('إعداد الشعب'!B15<>"نعم","",'شعبة 12'!I5) | M22: =IF('إعداد الشعب'!B15<>"نعم","",'شعبة 12'!K5) | N22: =IF('إعداد الشعب'!B15<>"نعم","",HYPERLINK("#'شعبة 12'!A1","فتح"))
A23: =13 -> 13 | B23: =IF('إعداد الشعب'!B16<>"نعم","",'إعداد الشعب'!H16) | C23: =IF('إعداد الشعب'!B16<>"نعم","",'إعداد الشعب'!C16) | D23: =IF('إعداد الشعب'!B16<>"نعم","",'إعداد الشعب'!D16) | E23: =IF('إعداد الشعب'!B16<>"نعم","",'إعداد الشعب'!E16) | F23: =IF('إعداد الشعب'!B16<>"نعم","",IF('إعداد الشعب'!F16="",الإعدادات!B6,'إعداد الشعب'!F16)) | G23: =IF('إعداد الشعب'!B16<>"نعم","",IF('إعداد الشعب'!G16="",الإعدادات!B7,'إعداد الشعب'!G16)) | H23: =IF('إعداد الشعب'!B16<>"نعم","",'شعبة 13'!A5) | I23: =IF('إعداد الشعب'!B16<>"نعم","",'شعبة 13'!C5) | J23: =IF('إعداد الشعب'!B16<>"نعم","",'شعبة 13'!E5) | K23: =IF('إعداد الشعب'!B16<>"نعم","",'شعبة 13'!G5) | L23: =IF('إعداد الشعب'!B16<>"نعم","",'شعبة 13'!I5) | M23: =IF('إعداد الشعب'!B16<>"نعم","",'شعبة 13'!K5) | N23: =IF('إعداد الشعب'!B16<>"نعم","",HYPERLINK("#'شعبة 13'!A1","فتح"))
A24: =14 -> 14 | B24: =IF('إعداد الشعب'!B17<>"نعم","",'إعداد الشعب'!H17) | C24: =IF('إعداد الشعب'!B17<>"نعم","",'إعداد الشعب'!C17) | D24: =IF('إعداد الشعب'!B17<>"نعم","",'إعداد الشعب'!D17) | E24: =IF('إعداد الشعب'!B17<>"نعم","",'إعداد الشعب'!E17) | F24: =IF('إعداد الشعب'!B17<>"نعم","",IF('إعداد الشعب'!F17="",الإعدادات!B6,'إعداد الشعب'!F17)) | G24: =IF('إعداد الشعب'!B17<>"نعم","",IF('إعداد الشعب'!G17="",الإعدادات!B7,'إعداد الشعب'!G17)) | H24: =IF('إعداد الشعب'!B17<>"نعم","",'شعبة 14'!A5) | I24: =IF('إعداد الشعب'!B17<>"نعم","",'شعبة 14'!C5) | J24: =IF('إعداد الشعب'!B17<>"نعم","",'شعبة 14'!E5) | K24: =IF('إعداد الشعب'!B17<>"نعم","",'شعبة 14'!G5) | L24: =IF('إعداد الشعب'!B17<>"نعم","",'شعبة 14'!I5) | M24: =IF('إعداد الشعب'!B17<>"نعم","",'شعبة 14'!K5) | N24: =IF('إعداد الشعب'!B17<>"نعم","",HYPERLINK("#'شعبة 14'!A1","فتح"))
A25: =15 -> 15 | B25: =IF('إعداد الشعب'!B18<>"نعم","",'إعداد الشعب'!H18) | C25: =IF('إعداد الشعب'!B18<>"نعم","",'إعداد الشعب'!C18) | D25: =IF('إعداد الشعب'!B18<>"نعم","",'إعداد الشعب'!D18) | E25: =IF('إعداد الشعب'!B18<>"نعم","",'إعداد الشعب'!E18) | F25: =IF('إعداد الشعب'!B18<>"نعم","",IF('إعداد الشعب'!F18="",الإعدادات!B6,'إعداد الشعب'!F18)) | G25: =IF('إعداد الشعب'!B18<>"نعم","",IF('إعداد الشعب'!G18="",الإعدادات!B7,'إعداد الشعب'!G18)) | H25: =IF('إعداد الشعب'!B18<>"نعم","",'شعبة 15'!A5) | I25: =IF('إعداد الشعب'!B18<>"نعم","",'شعبة 15'!C5) | J25: =IF('إعداد الشعب'!B18<>"نعم","",'شعبة 15'!E5) | K25: =IF('إعداد الشعب'!B18<>"نعم","",'شعبة 15'!G5) | L25: =IF('إعداد الشعب'!B18<>"نعم","",'شعبة 15'!I5) | M25: =IF('إعداد الشعب'!B18<>"نعم","",'شعبة 15'!K5) | N25: =IF('إعداد الشعب'!B18<>"نعم","",HYPERLINK("#'شعبة 15'!A1","فتح"))
A26: =16 -> 16 | B26: =IF('إعداد الشعب'!B19<>"نعم","",'إعداد الشعب'!H19) | C26: =IF('إعداد الشعب'!B19<>"نعم","",'إعداد الشعب'!C19) | D26: =IF('إعداد الشعب'!B19<>"نعم","",'إعداد الشعب'!D19) | E26: =IF('إعداد الشعب'!B19<>"نعم","",'إعداد الشعب'!E19) | F26: =IF('إعداد الشعب'!B19<>"نعم","",IF('إعداد الشعب'!F19="",الإعدادات!B6,'إعداد الشعب'!F19)) | G26: =IF('إعداد الشعب'!B19<>"نعم","",IF('إعداد الشعب'!G19="",الإعدادات!B7,'إعداد الشعب'!G19)) | H26: =IF('إعداد الشعب'!B19<>"نعم","",'شعبة 16'!A5) | I26: =IF('إعداد الشعب'!B19<>"نعم","",'شعبة 16'!C5) | J26: =IF('إعداد الشعب'!B19<>"نعم","",'شعبة 16'!E5) | K26: =IF('إعداد الشعب'!B19<>"نعم","",'شعبة 16'!G5) | L26: =IF('إعداد الشعب'!B19<>"نعم","",'شعبة 16'!I5) | M26: =IF('إعداد الشعب'!B19<>"نعم","",'شعبة 16'!K5) | N26: =IF('إعداد الشعب'!B19<>"نعم","",HYPERLINK("#'شعبة 16'!A1","فتح"))
A27: =17 -> 17 | B27: =IF('إعداد الشعب'!B20<>"نعم","",'إعداد الشعب'!H20) | C27: =IF('إعداد الشعب'!B20<>"نعم","",'إعداد الشعب'!C20) | D27: =IF('إعداد الشعب'!B20<>"نعم","",'إعداد الشعب'!D20) | E27: =IF('إعداد الشعب'!B20<>"نعم","",'إعداد الشعب'!E20) | F27: =IF('إعداد الشعب'!B20<>"نعم","",IF('إعداد الشعب'!F20="",الإعدادات!B6,'إعداد الشعب'!F20)) | G27: =IF('إعداد الشعب'!B20<>"نعم","",IF('إعداد الشعب'!G20="",الإعدادات!B7,'إعداد الشعب'!G20)) | H27: =IF('إعداد الشعب'!B20<>"نعم","",'شعبة 17'!A5) | I27: =IF('إعداد الشعب'!B20<>"نعم","",'شعبة 17'!C5) | J27: =IF('إعداد الشعب'!B20<>"نعم","",'شعبة 17'!E5) | K27: =IF('إعداد الشعب'!B20<>"نعم","",'شعبة 17'!G5) | L27: =IF('إعداد الشعب'!B20<>"نعم","",'شعبة 17'!I5) | M27: =IF('إعداد الشعب'!B20<>"نعم","",'شعبة 17'!K5) | N27: =IF('إعداد الشعب'!B20<>"نعم","",HYPERLINK("#'شعبة 17'!A1","فتح"))
A28: =18 -> 18 | B28: =IF('إعداد الشعب'!B21<>"نعم","",'إعداد الشعب'!H21) | C28: =IF('إعداد الشعب'!B21<>"نعم","",'إعداد الشعب'!C21) | D28: =IF('إعداد الشعب'!B21<>"نعم","",'إعداد الشعب'!D21) | E28: =IF('إعداد الشعب'!B21<>"نعم","",'إعداد الشعب'!E21) | F28: =IF('إعداد الشعب'!B21<>"نعم","",IF('إعداد الشعب'!F21="",الإعدادات!B6,'إعداد الشعب'!F21)) | G28: =IF('إعداد الشعب'!B21<>"نعم","",IF('إعداد الشعب'!G21="",الإعدادات!B7,'إعداد الشعب'!G21)) | H28: =IF('إعداد الشعب'!B21<>"نعم","",'شعبة 18'!A5) | I28: =IF('إعداد الشعب'!B21<>"نعم","",'شعبة 18'!C5) | J28: =IF('إعداد الشعب'!B21<>"نعم","",'شعبة 18'!E5) | K28: =IF('إعداد الشعب'!B21<>"نعم","",'شعبة 18'!G5) | L28: =IF('إعداد الشعب'!B21<>"نعم","",'شعبة 18'!I5) | M28: =IF('إعداد الشعب'!B21<>"نعم","",'شعبة 18'!K5) | N28: =IF('إعداد الشعب'!B21<>"نعم","",HYPERLINK("#'شعبة 18'!A1","فتح"))
A29: =19 -> 19 | B29: =IF('إعداد الشعب'!B22<>"نعم","",'إعداد الشعب'!H22) | C29: =IF('إعداد الشعب'!B22<>"نعم","",'إعداد الشعب'!C22) | D29: =IF('إعداد الشعب'!B22<>"نعم","",'إعداد الشعب'!D22) | E29: =IF('إعداد الشعب'!B22<>"نعم","",'إعداد الشعب'!E22) | F29: =IF('إعداد الشعب'!B22<>"نعم","",IF('إعداد الشعب'!F22="",الإعدادات!B6,'إعداد الشعب'!F22)) | G29: =IF('إعداد الشعب'!B22<>"نعم","",IF('إعداد الشعب'!G22="",الإعدادات!B7,'إعداد الشعب'!G22)) | H29: =IF('إعداد الشعب'!B22<>"نعم","",'شعبة 19'!A5) | I29: =IF('إعداد الشعب'!B22<>"نعم","",'شعبة 19'!C5) | J29: =IF('إعداد الشعب'!B22<>"نعم","",'شعبة 19'!E5) | K29: =IF('إعداد الشعب'!B22<>"نعم","",'شعبة 19'!G5) | L29: =IF('إعداد الشعب'!B22<>"نعم","",'شعبة 19'!I5) | M29: =IF('إعداد الشعب'!B22<>"نعم","",'شعبة 19'!K5) | N29: =IF('إعداد الشعب'!B22<>"نعم","",HYPERLINK("#'شعبة 19'!A1","فتح"))
A30: =20 -> 20 | B30: =IF('إعداد الشعب'!B23<>"نعم","",'إعداد الشعب'!H23) | C30: =IF('إعداد الشعب'!B23<>"نعم","",'إعداد الشعب'!C23) | D30: =IF('إعداد الشعب'!B23<>"نعم","",'إعداد الشعب'!D23) | E30: =IF('إعداد الشعب'!B23<>"نعم","",'إعداد الشعب'!E23) | F30: =IF('إعداد الشعب'!B23<>"نعم","",IF('إعداد الشعب'!F23="",الإعدادات!B6,'إعداد الشعب'!F23)) | G30: =IF('إعداد الشعب'!B23<>"نعم","",IF('إعداد الشعب'!G23="",الإعدادات!B7,'إعداد الشعب'!G23)) | H30: =IF('إعداد الشعب'!B23<>"نعم","",'شعبة 20'!A5) | I30: =IF('إعداد الشعب'!B23<>"نعم","",'شعبة 20'!C5) | J30: =IF('إعداد الشعب'!B23<>"نعم","",'شعبة 20'!E5) | K30: =IF('إعداد الشعب'!B23<>"نعم","",'شعبة 20'!G5) | L30: =IF('إعداد الشعب'!B23<>"نعم","",'شعبة 20'!I5) | M30: =IF('إعداد الشعب'!B23<>"نعم","",'شعبة 20'!K5) | N30: =IF('إعداد الشعب'!B23<>"نعم","",HYPERLINK("#'شعبة 20'!A1","فتح"))

Sheet شعبة 01
A1: =HYPERLINK("#'لوحة الشعب'!A1","⌂ "&IF('إعداد الشعب'!B4<>"نعم","صفحة غير مفعلة","سجل الفصل الأول – "&'إعداد الشعب'!C4&" – الصف "&'إعداد الشعب'!D4&" – شعبة "&'إعداد الشعب'!E4&" – "&IF('إعداد الشعب'!F4="",الإعدادات!B6,'إعداد الشعب'!F4))) -> ⌂ سجل الفصل الأول – إعدادية – الصف 7 – شعبة 1 – الحوسبة وتكنولوجيا المعلومات
A2: المرحلة | B2: ='إعداد الشعب'!C4 -> إعدادية | C2: الصف | D2: ='إعداد الشعب'!D4 -> 7 | E2: الشعبة | F2: ='إعداد الشعب'!E4 -> 1 | G2: المادة | H2: =IF('إعداد الشعب'!F4="",الإعدادات!B6,'إعداد الشعب'!F4) -> الحوسبة وتكنولوجيا المعلومات | I2: المعلم | J2: =IF('إعداد الشعب'!G4="",الإعدادات!B7,'إعداد الشعب'!G4) -> جمال صالح
A4: الطلاب | C4: الملاحظات | E4: الغياب | G4: النوم | I4: حل الواجبات | K4: تميز
A5: =COUNTIFS(B9:B48,"<>",C9:C48,"<>لا") -> 0 | C5: =SUM(AF53:AF92)+SUM(Z99:Z138)+SUM(AF145:AF184)+SUM(W191:W230) -> 0 | E5: =SUM(AB53:AB92)+SUM(V99:V138)+SUM(AB145:AB184)+SUM(S191:S230) -> 0 | G5: =SUM(Z53:Z92)+SUM(T99:T138)+SUM(Z145:Z184)+SUM(Q191:Q230) -> 0 | I5: =SUM(AD53:AD92)+SUM(X99:X138)+SUM(AD145:AD184)+SUM(U191:U230) -> 0 | K5: =SUM(AE53:AE92)+SUM(Y99:Y138)+SUM(AE145:AE184)+SUM(V191:V230) -> 0
A7: =HYPERLINK("#'شعبة 01'!A50","سبتمبر") -> سبتمبر | B7: =HYPERLINK("#'شعبة 01'!A96","أكتوبر") -> أكتوبر | C7: =HYPERLINK("#'شعبة 01'!A142","نوفمبر") -> نوفمبر | D7: =HYPERLINK("#'شعبة 01'!A188","ديسمبر") -> ديسمبر | E7: =HYPERLINK("#'لوحة الشعب'!A1","لوحة الشعب") -> لوحة الشعب
A8: م | B8: اسم الطالب | C8: نشط؟ | D8: ملاحظات | F8: تقرير سريع لطالب – الفصل الدراسي الأول
A9: 1 | F9: اختر الطالب | G9: اسامه اشرف انور فتح الباب متولي
A10: 2 | F10: الخيار | G10: سبتمبر | H10: أكتوبر | I10: نوفمبر | J10: ديسمبر | K10: الإجمالي
A11: 3 | F11: =الإعدادات!H4 -> كتاب | G11: =IF($G$9="","",SUMIF($B$53:$B$92,$G$9,$Y$53:$Y$92)) -> 0 | H11: =IF($G$9="","",SUMIF($B$99:$B$138,$G$9,$S$99:$S$138)) -> 0 | I11: =IF($G$9="","",SUMIF($B$145:$B$184,$G$9,$Y$145:$Y$184)) -> 0 | J11: =IF($G$9="","",SUMIF($B$191:$B$230,$G$9,$P$191:$P$230)) -> 0 | K11: =SUM(G11:J11) -> 0
A12: 4 | F12: =الإعدادات!H5 -> نوم | G12: =IF($G$9="","",SUMIF($B$53:$B$92,$G$9,$Z$53:$Z$92)) -> 0 | H12: =IF($G$9="","",SUMIF($B$99:$B$138,$G$9,$T$99:$T$138)) -> 0 | I12: =IF($G$9="","",SUMIF($B$145:$B$184,$G$9,$Z$145:$Z$184)) -> 0 | J12: =IF($G$9="","",SUMIF($B$191:$B$230,$G$9,$Q$191:$Q$230)) -> 0 | K12: =SUM(G12:J12) -> 0
A13: 5 | F13: =الإعدادات!H6 -> سلوك | G13: =IF($G$9="","",SUMIF($B$53:$B$92,$G$9,$AA$53:$AA$92)) -> 0 | H13: =IF($G$9="","",SUMIF($B$99:$B$138,$G$9,$U$99:$U$138)) -> 0 | I13: =IF($G$9="","",SUMIF($B$145:$B$184,$G$9,$AA$145:$AA$184)) -> 0 | J13: =IF($G$9="","",SUMIF($B$191:$B$230,$G$9,$R$191:$R$230)) -> 0 | K13: =SUM(G13:J13) -> 0
A14: 6 | F14: =الإعدادات!H7 -> غياب | G14: =IF($G$9="","",SUMIF($B$53:$B$92,$G$9,$AB$53:$AB$92)) -> 0 | H14: =IF($G$9="","",SUMIF($B$99:$B$138,$G$9,$V$99:$V$138)) -> 0 | I14: =IF($G$9="","",SUMIF($B$145:$B$184,$G$9,$AB$145:$AB$184)) -> 0 | J14: =IF($G$9="","",SUMIF($B$191:$B$230,$G$9,$S$191:$S$230)) -> 0 | K14: =SUM(G14:J14) -> 0
A15: 7 | F15: =الإعدادات!H8 -> تأخر | G15: =IF($G$9="","",SUMIF($B$53:$B$92,$G$9,$AC$53:$AC$92)) -> 0 | H15: =IF($G$9="","",SUMIF($B$99:$B$138,$G$9,$W$99:$W$138)) -> 0 | I15: =IF($G$9="","",SUMIF($B$145:$B$184,$G$9,$AC$145:$AC$184)) -> 0 | J15: =IF($G$9="","",SUMIF($B$191:$B$230,$G$9,$T$191:$T$230)) -> 0 | K15: =SUM(G15:J15) -> 0
A16: 8 | F16: =الإعدادات!H9 -> حل الواجبات | G16: =IF($G$9="","",SUMIF($B$53:$B$92,$G$9,$AD$53:$AD$92)) -> 0 | H16: =IF($G$9="","",SUMIF($B$99:$B$138,$G$9,$X$99:$X$138)) -> 0 | I16: =IF($G$9="","",SUMIF($B$145:$B$184,$G$9,$AD$145:$AD$184)) -> 0 | J16: =IF($G$9="","",SUMIF($B$191:$B$230,$G$9,$U$191:$U$230)) -> 0 | K16: =SUM(G16:J16) -> 0
A17: 9 | F17: =الإعدادات!H10 -> تميز ★ | G17: =IF($G$9="","",SUMIF($B$53:$B$92,$G$9,$AE$53:$AE$92)) -> 0 | H17: =IF($G$9="","",SUMIF($B$99:$B$138,$G$9,$Y$99:$Y$138)) -> 0 | I17: =IF($G$9="","",SUMIF($B$145:$B$184,$G$9,$AE$145:$AE$184)) -> 0 | J17: =IF($G$9="","",SUMIF($B$191:$B$230,$G$9,$V$191:$V$230)) -> 0 | K17: =SUM(G17:J17) -> 0
A18: 10
A19: 11 | F19: الفصل الدراسي الأول: أدخل أسماء طلاب الشعبة أعلى الصفحة، ثم استخدم القوائم المنسدلة في سبتمبر–ديسمبر 2026. إجازة منتصف الفصل (25–29 أكتوبر) مستبعدة من التواريخ.
A20: 12
A21: 13
A22: 14
A23: 15
A24: 16
A25: 17
A26: 18
A27: 19
A28: 20
A29: 21
A30: 22
A31: 23
... A48: 40
A50: متابعة شهر سبتمبر 2026
A51: بيانات الطالب | C51: المتابعة اليومية | Y51: ملخص الشهر
A52: م | B52: اسم الطالب | C52: الثلاثاء 01/09 | D52: الأربعاء 02/09 | E52: الخميس 03/09 | F52: الأحد 06/09 | G52: الاثنين 07/09 | H52: الثلاثاء 08/09 | I52: الأربعاء 09/09 | J52: الخميس 10/09 | K52: الأحد 13/09 | L52: الاثنين 14/09 | M52: الثلاثاء 15/09 | N52: الأربعاء 16/09 | O52: الخميس 17/09 | P52: الأحد 20/09 | Q52: الاثنين 21/09 | R52: الثلاثاء 22/09 | S52: الأربعاء 23/09 | T52: الخميس 24/09 | U52: الأحد 27/09 | V52: الاثنين 28/09 | W52: الثلاثاء 29/09 | X52: الأربعاء 30/09 | Y52: =الإعدادات!H4 -> كتاب | Z52: =الإعدادات!H5 -> نوم | AA52: =الإعدادات!H6 -> سلوك | AB52: =الإعدادات!H7 -> غياب | AC52: =الإعدادات!H8 -> تأخر | AD52: =الإعدادات!H9 -> حل الواجبات | AE52: =الإعدادات!H10 -> تميز ★ | AF52: مجموع الملاحظات
A53: =IF(OR($B$9="",$C$9="لا"),"",$A$9) | B53: =IF(OR($B$9="",$C$9="لا"),"",$B$9) | K53: تميز ★ | Y53: =IF($B53="","",COUNTIF($C53:$X53,الإعدادات!$H$4)) | Z53: =IF($B53="","",COUNTIF($C53:$X53,الإعدادات!$H$5)) | AA53: =IF($B53="","",COUNTIF($C53:$X53,الإعدادات!$H$6)) | AB53: =IF($B53="","",COUNTIF($C53:$X53,الإعدادات!$H$7)) | AC53: =IF($B53="","",COUNTIF($C53:$X53,الإعدادات!$H$8)) | AD53: =IF($B53="","",COUNTIF($C53:$X53,الإعدادات!$H$9)) | AE53: =IF($B53="","",COUNTIF($C53:$X53,الإعدادات!$H$10)) | AF53: =IF($B53="","",SUM(Y53:AC53))
A54: =IF(OR($B$10="",$C$10="لا"),"",$A$10) | B54: =IF(OR($B$10="",$C$10="لا"),"",$B$10) | K54: سلوك | Y54: =IF($B54="","",COUNTIF($C54:$X54,الإعدادات!$H$4)) | Z54: =IF($B54="","",COUNTIF($C54:$X54,الإعدادات!$H$5)) | AA54: =IF($B54="","",COUNTIF($C54:$X54,الإعدادات!$H$6)) | AB54: =IF($B54="","",COUNTIF($C54:$X54,الإعدادات!$H$7)) | AC54: =IF($B54="","",COUNTIF($C54:$X54,الإعدادات!$H$8)) | AD54: =IF($B54="","",COUNTIF($C54:$X54,الإعدادات!$H$9)) | AE54: =IF($B54="","",COUNTIF($C54:$X54,الإعدادات!$H$10)) | AF54: =IF($B54="","",SUM(Y54:AC54))
A55: =IF(OR($B$11="",$C$11="لا"),"",$A$11) | B55: =IF(OR($B$11="",$C$11="لا"),"",$B$11) | Y55: =IF($B55="","",COUNTIF($C55:$X55,الإعدادات!$H$4)) | Z55: =IF($B55="","",COUNTIF($C55:$X55,الإعدادات!$H$5)) | AA55: =IF($B55="","",COUNTIF($C55:$X55,الإعدادات!$H$6)) | AB55: =IF($B55="","",COUNTIF($C55:$X55,الإعدادات!$H$7)) | AC55: =IF($B55="","",COUNTIF($C55:$X55,الإعدادات!$H$8)) | AD55: =IF($B55="","",COUNTIF($C55:$X55,الإعدادات!$H$9)) | AE55: =IF($B55="","",COUNTIF($C55:$X55,الإعدادات!$H$10)) | AF55: =IF($B55="","",SUM(Y55:AC55))
A56: =IF(OR($B$12="",$C$12="لا"),"",$A$12) | B56: =IF(OR($B$12="",$C$12="لا"),"",$B$12) | Y56: =IF($B56="","",COUNTIF($C56:$X56,الإعدادات!$H$4)) | Z56: =IF($B56="","",COUNTIF($C56:$X56,الإعدادات!$H$5)) | AA56: =IF($B56="","",COUNTIF($C56:$X56,الإعدادات!$H$6)) | AB56: =IF($B56="","",COUNTIF($C56:$X56,الإعدادات!$H$7)) | AC56: =IF($B56="","",COUNTIF($C56:$X56,الإعدادات!$H$8)) | AD56: =IF($B56="","",COUNTIF($C56:$X56,الإعدادات!$H$9)) | AE56: =IF($B56="","",COUNTIF($C56:$X56,الإعدادات!$H$10)) | AF56: =IF($B56="","",SUM(Y56:AC56))
A57: =IF(OR($B$13="",$C$13="لا"),"",$A$13) | B57: =IF(OR($B$13="",$C$13="لا"),"",$B$13) | Y57: =IF($B57="","",COUNTIF($C57:$X57,الإعدادات!$H$4)) | Z57: =IF($B57="","",COUNTIF($C57:$X57,الإعدادات!$H$5)) | AA57: =IF($B57="","",COUNTIF($C57:$X57,الإعدادات!$H$6)) | AB57: =IF($B57="","",COUNTIF($C57:$X57,الإعدادات!$H$7)) | AC57: =IF($B57="","",COUNTIF($C57:$X57,الإعدادات!$H$8)) | AD57: =IF($B57="","",COUNTIF($C57:$X57,الإعدادات!$H$9)) | AE57: =IF($B57="","",COUNTIF($C57:$X57,الإعدادات!$H$10)) | AF57: =IF($B57="","",SUM(Y57:AC57))
A58: =IF(OR($B$14="",$C$14="لا"),"",$A$14) | B58: =IF(OR($B$14="",$C$14="لا"),"",$B$14) | K58: سلوك | Y58: =IF($B58="","",COUNTIF($C58:$X58,الإعدادات!$H$4)) | Z58: =IF($B58="","",COUNTIF($C58:$X58,الإعدادات!$H$5)) | AA58: =IF($B58="","",COUNTIF($C58:$X58,الإعدادات!$H$6)) | AB58: =IF($B58="","",COUNTIF($C58:$X58,الإعدادات!$H$7)) | AC58: =IF($B58="","",COUNTIF($C58:$X58,الإعدادات!$H$8)) | AD58: =IF($B58="","",COUNTIF($C58:$X58,الإعدادات!$H$9)) | AE58: =IF($B58="","",COUNTIF($C58:$X58,الإعدادات!$H$10)) | AF58: =IF($B58="","",SUM(Y58:AC58))
A59: =IF(OR($B$15="",$C$15="لا"),"",$A$15) | B59: =IF(OR($B$15="",$C$15="لا"),"",$B$15) | Y59: =IF($B59="","",COUNTIF($C59:$X59,الإعدادات!$H$4)) | Z59: =IF($B59="","",COUNTIF($C59:$X59,الإعدادات!$H$5)) | AA59: =IF($B59="","",COUNTIF($C59:$X59,الإعدادات!$H$6)) | AB59: =IF($B59="","",COUNTIF($C59:$X59,الإعدادات!$H$7)) | AC59: =IF($B59="","",COUNTIF($C59:$X59,الإعدادات!$H$8)) | AD59: =IF($B59="","",COUNTIF($C59:$X59,الإعدادات!$H$9)) | AE59: =IF($B59="","",COUNTIF($C59:$X59,الإعدادات!$H$10)) | AF59: =IF($B59="","",SUM(Y59:AC59))
...

Sheet شعبة 02
A1: =HYPERLINK("#'لوحة الشعب'!A1","⌂ "&IF('إعداد الشعب'!B5<>"نعم","صفحة غير مفعلة","سجل الفصل الأول – "&'إعداد الشعب'!C5&" – الصف "&'إعداد الشعب'!D5&" – شعبة "&'إعداد الشعب'!E5&" – "&IF('إعداد الشعب'!F5="",الإعدادات!B6,'إعداد الشعب'!F5))) -> ⌂ سجل الفصل الأول – إعدادية – الصف 7 – شعبة 2 – الحوسبة وتكنولوجيا المعلومات
A2: المرحلة | B2: ='إعداد الشعب'!C5 -> إعدادية | C2: الصف | D2: ='إعداد الشعب'!D5 -> 7 | E2: الشعبة | F2: ='إعداد الشعب'!E5 -> 2 | G2: المادة | H2: =IF('إعداد الشعب'!F5="",الإعدادات!B6,'إعداد الشعب'!F5) -> الحوسبة وتكنولوجيا المعلومات | I2: المعلم | J2: =IF('إعداد الشعب'!G5="",الإعدادات!B7,'إعداد الشعب'!G5) -> جمال صالح
A4: الطلاب | C4: الملاحظات | E4: الغياب | G4: النوم | I4: حل الواجبات | K4: تميز
A5: =COUNTIFS(B9:B48,"<>",C9:C48,"<>لا") -> 0 | C5: =SUM(AF53:AF92)+SUM(Z99:Z138)+SUM(AF145:AF184)+SUM(W191:W230) -> 0 | E5: =SUM(AB53:AB92)+SUM(V99:V138)+SUM(AB145:AB184)+SUM(S191:S230) -> 0 | G5: =SUM(Z53:Z92)+SUM(T99:T138)+SUM(Z145:Z184)+SUM(Q191:Q230) -> 0 | I5: =SUM(AD53:AD92)+SUM(X99:X138)+SUM(AD145:AD184)+SUM(U191:U230) -> 0 | K5: =SUM(AE53:AE92)+SUM(Y99:Y138)+SUM(AE145:AE184)+SUM(V191:V230) -> 0
A7: =HYPERLINK("#'شعبة 02'!A50","سبتمبر") -> سبتمبر | B7: =HYPERLINK("#'شعبة 02'!A96","أكتوبر") -> أكتوبر | C7: =HYPERLINK("#'شعبة 02'!A142","نوفمبر") -> نوفمبر | D7: =HYPERLINK("#'شعبة 02'!A188","ديسمبر") -> ديسمبر | E7: =HYPERLINK("#'لوحة الشعب'!A1","لوحة الشعب") -> لوحة الشعب
A8: م | B8: اسم الطالب | C8: نشط؟ | D8: ملاحظات | F8: تقرير سريع لطالب – الفصل الدراسي الأول
A9: 1 | F9: اختر الطالب
A10: 2 | F10: الخيار | G10: سبتمبر | H10: أكتوبر | I10: نوفمبر | J10: ديسمبر | K10: الإجمالي
A11: 3 | F11: =الإعدادات!H4 -> كتاب | G11: =IF($G$9="","",SUMIF($B$53:$B$92,$G$9,$Y$53:$Y$92)) | H11: =IF($G$9="","",SUMIF($B$99:$B$138,$G$9,$S$99:$S$138)) | I11: =IF($G$9="","",SUMIF($B$145:$B$184,$G$9,$Y$145:$Y$184)) | J11: =IF($G$9="","",SUMIF($B$191:$B$230,$G$9,$P$191:$P$230)) | K11: =SUM(G11:J11) -> 0
A12: 4 | F12: =الإعدادات!H5 -> نوم | G12: =IF($G$9="","",SUMIF($B$53:$B$92,$G$9,$Z$53:$Z$92)) | H12: =IF($G$9="","",SUMIF($B$99:$B$138,$G$9,$T$99:$T$138)) | I12: =IF($G$9="","",SUMIF($B$145:$B$184,$G$9,$Z$145:$Z$184)) | J12: =IF($G$9="","",SUMIF($B$191:$B$230,$G$9,$Q$191:$Q$230)) | K12: =SUM(G12:J12) -> 0
A13: 5 | F13: =الإعدادات!H6 -> سلوك | G13: =IF($G$9="","",SUMIF($B$53:$B$92,$G$9,$AA$53:$AA$92)) | H13: =IF($G$9="","",SUMIF($B$99:$B$138,$G$9,$U$99:$U$138)) | I13: =IF($G$9="","",SUMIF($B$145:$B$184,$G$9,$AA$145:$AA$184)) | J13: =IF($G$9="","",SUMIF($B$191:$B$230,$G$9,$R$191:$R$230)) | K13: =SUM(G13:J13) -> 0
A14: 6 | F14: =الإعدادات!H7 -> غياب | G14: =IF($G$9="","",SUMIF($B$53:$B$92,$G$9,$AB$53:$AB$92)) | H14: =IF($G$9="","",SUMIF($B$99:$B$138,$G$9,$V$99:$V$138)) | I14: =IF($G$9="","",SUMIF($B$145:$B$184,$G$9,$AB$145:$AB$184)) | J14: =IF($G$9="","",SUMIF($B$191:$B$230,$G$9,$S$191:$S$230)) | K14: =SUM(G14:J14) -> 0
A15: 7 | F15: =الإعدادات!H8 -> تأخر | G15: =IF($G$9="","",SUMIF($B$53:$B$92,$G$9,$AC$53:$AC$92)) | H15: =IF($G$9="","",SUMIF($B$99:$B$138,$G$9,$W$99:$W$138)) | I15: =IF($G$9="","",SUMIF($B$145:$B$184,$G$9,$AC$145:$AC$184)) | J15: =IF($G$9="","",SUMIF($B$191:$B$230,$G$9,$T$191:$T$230)) | K15: =SUM(G15:J15) -> 0
A16: 8 | F16: =الإعدادات!H9 -> حل الواجبات | G16: =IF($G$9="","",SUMIF($B$53:$B$92,$G$9,$AD$53:$AD$92)) | H16: =IF($G$9="","",SUMIF($B$99:$B$138,$G$9,$X$99:$X$138)) | I16: =IF($G$9="","",SUMIF($B$145:$B$184,$G$9,$AD$145:$AD$184)) | J16: =IF($G$9="","",SUMIF($B$191:$B$230,$G$9,$U$191:$U$230)) | K16: =SUM(G16:J16) -> 0
A17: 9 | F17: =الإعدادات!H10 -> تميز ★ | G17: =IF($G$9="","",SUMIF($B$53:$B$92,$G$9,$AE$53:$AE$92)) | H17: =IF($G$9="","",SUMIF($B$99:$B$138,$G$9,$Y$99:$Y$138)) | I17: =IF($G$9="","",SUMIF($B$145:$B$184,$G$9,$AE$145:$AE$184)) | J17: =IF($G$9="","",SUMIF($B$191:$B$230,$G$9,$V$191:$V$230)) | K17: =SUM(G17:J17) -> 0
A18: 10
A19: 11 | F19: الفصل الدراسي الأول: أدخل أسماء طلاب الشعبة أعلى الصفحة، ثم استخدم القوائم المنسدلة في سبتمبر–ديسمبر 2026. إجازة منتصف الفصل (25–29 أكتوبر) مستبعدة من التواريخ.
A20: 12
A21: 13
A22: 14
A23: 15
A24: 16
A25: 17
A26: 18
A27: 19
A28: 20
A29: 21
A30: 22
A31: 23
... A48: 40
A50: متابعة شهر سبتمبر 2026
A51: بيانات الطالب | C51: المتابعة اليومية | Y51: ملخص الشهر
A52: م | B52: اسم الطالب | C52: الثلاثاء 01/09 | D52: الأربعاء 02/09 | E52: الخميس 03/09 | F52: الأحد 06/09 | G52: الاثنين 07/09 | H52: الثلاثاء 08/09 | I52: الأربعاء 09/09 | J52: الخميس 10/09 | K52: الأحد 13/09 | L52: الاثنين 14/09 | M52: الثلاثاء 15/09 | N52: الأربعاء 16/09 | O52: الخميس 17/09 | P52: الأحد 20/09 | Q52: الاثنين 21/09 | R52: الثلاثاء 22/09 | S52: الأربعاء 23/09 | T52: الخميس 24/09 | U52: الأحد 27/09 | V52: الاثنين 28/09 | W52: الثلاثاء 29/09 | X52: الأربعاء 30/09 | Y52: =الإعدادات!H4 -> كتاب | Z52: =الإعدادات!H5 -> نوم | AA52: =الإعدادات!H6 -> سلوك | AB52: =الإعدادات!H7 -> غياب | AC52: =الإعدادات!H8 -> تأخر | AD52: =الإعدادات!H9 -> حل الواجبات | AE52: =الإعدادات!H10 -> تميز ★ | AF52: مجموع الملاحظات
A53: =IF(OR($B$9="",$C$9="لا"),"",$A$9) | B53: =IF(OR($B$9="",$C$9="لا"),"",$B$9) | Y53: =IF($B53="","",COUNTIF($C53:$X53,الإعدادات!$H$4)) | Z53: =IF($B53="","",COUNTIF($C53:$X53,الإعدادات!$H$5)) | AA53: =IF($B53="","",COUNTIF($C53:$X53,الإعدادات!$H$6)) | AB53: =IF($B53="","",COUNTIF($C53:$X53,الإعدادات!$H$7)) | AC53: =IF($B53="","",COUNTIF($C53:$X53,الإعدادات!$H$8)) | AD53: =IF($B53="","",COUNTIF($C53:$X53,الإعدادات!$H$9)) | AE53: =IF($B53="","",COUNTIF($C53:$X53,الإعدادات!$H$10)) | AF53: =IF($B53="","",SUM(Y53:AC53))
A54: =IF(OR($B$10="",$C$10="لا"),"",$A$10) | B54: =IF(OR($B$10="",$C$10="لا"),"",$B$10) | Y54: =IF($B54="","",COUNTIF($C54:$X54,الإعدادات!$H$4)) | Z54: =IF($B54="","",COUNTIF($C54:$X54,الإعدادات!$H$5)) | AA54: =IF($B54="","",COUNTIF($C54:$X54,الإعدادات!$H$6)) | AB54: =IF($B54="","",COUNTIF($C54:$X54,الإعدادات!$H$7)) | AC54: =IF($B54="","",COUNTIF($C54:$X54,الإعدادات!$H$8)) | AD54: =IF($B54="","",COUNTIF($C54:$X54,الإعدادات!$H$9)) | AE54: =IF($B54="","",COUNTIF($C54:$X54,الإعدادات!$H$10)) | AF54: =IF($B54="","",SUM(Y54:AC54))
A55: =IF(OR($B$11="",$C$11="لا"),"",$A$11) | B55: =IF(OR($B$11="",$C$11="لا"),"",$B$11) | Y55: =IF($B55="","",COUNTIF($C55:$X55,الإعدادات!$H$4)) | Z55: =IF($B55="","",COUNTIF($C55:$X55,الإعدادات!$H$5)) | AA55: =IF($B55="","",COUNTIF($C55:$X55,الإعدادات!$H$6)) | AB55: =IF($B55="","",COUNTIF($C55:$X55,الإعدادات!$H$7)) | AC55: =IF($B55="","",COUNTIF($C55:$X55,الإعدادات!$H$8)) | AD55: =IF($B55="","",COUNTIF($C55:$X55,الإعدادات!$H$9)) | AE55: =IF($B55="","",COUNTIF($C55:$X55,الإعدادات!$H$10)) | AF55: =IF($B55="","",SUM(Y55:AC55))
A56: =IF(OR($B$12="",$C$12="لا"),"",$A$12) | B56: =IF(OR($B$12="",$C$12="لا"),"",$B$12) | Y56: =IF($B56="","",COUNTIF($C56:$X56,الإعدادات!$H$4)) | Z56: =IF($B56="","",COUNTIF($C56:$X56,الإعدادات!$H$5)) | AA56: =IF($B56="","",COUNTIF($C56:$X56,الإعدادات!$H$6)) | AB56: =IF($B56="","",COUNTIF($C56:$X56,الإعدادات!$H$7)) | AC56: =IF($B56="","",COUNTIF($C56:$X56,الإعدادات!$H$8)) | AD56: =IF($B56="","",COUNTIF($C56:$X56,الإعدادات!$H$9)) | AE56: =IF($B56="","",COUNTIF($C56:$X56,الإعدادات!$H$10)) | AF56: =IF($B56="","",SUM(Y56:AC56))
A57: =IF(OR($B$13="",$C$13="لا"),"",$A$13) | B57: =IF(OR($B$13="",$C$13="لا"),"",$B$13) | Y57: =IF($B57="","",COUNTIF($C57:$X57,الإعدادات!$H$4)) | Z57: =IF($B57="","",COUNTIF($C57:$X57,الإعدادات!$H$5)) | AA57: =IF($B57="","",COUNTIF($C57:$X57,الإعدادات!$H$6)) | AB57: =IF($B57="","",COUNTIF($C57:$X57,الإعدادات!$H$7)) | AC57: =IF($B57="","",COUNTIF($C57:$X57,الإعدادات!$H$8)) | AD57: =IF($B57="","",COUNTIF($C57:$X57,الإعدادات!$H$9)) | AE57: =IF($B57="","",COUNTIF($C57:$X57,الإعدادات!$H$10)) | AF57: =IF($B57="","",SUM(Y57:AC57))
A58: =IF(OR($B$14="",$C$14="لا"),"",$A$14) | B58: =IF(OR($B$14="",$C$14="لا"),"",$B$14) | Y58: =IF($B58="","",COUNTIF($C58:$X58,الإعدادات!$H$4)) | Z58: =IF($B58="","",COUNTIF($C58:$X58,الإعدادات!$H$5)) | AA58: =IF($B58="","",COUNTIF($C58:$X58,الإعدادات!$H$6)) | AB58: =IF($B58="","",COUNTIF($C58:$X58,الإعدادات!$H$7)) | AC58: =IF($B58="","",COUNTIF($C58:$X58,الإعدادات!$H$8)) | AD58: =IF($B58="","",COUNTIF($C58:$X58,الإعدادات!$H$9)) | AE58: =IF($B58="","",COUNTIF($C58:$X58,الإعدادات!$H$10)) | AF58: =IF($B58="","",SUM(Y58:AC58))
A59: =IF(OR($B$15="",$C$15="لا"),"",$A$15) | B59: =IF(OR($B$15="",$C$15="لا"),"",$B$15) | Y59: =IF($B59="","",COUNTIF($C59:$X59,الإعدادات!$H$4)) | Z59: =IF($B59="","",COUNTIF($C59:$X59,الإعدادات!$H$5)) | AA59: =IF($B59="","",COUNTIF($C59:$X59,الإعدادات!$H$6)) | AB59: =IF($B59="","",COUNTIF($C59:$X59,الإعدادات!$H$7)) | AC59: =IF($B59="","",COUNTIF($C59:$X59,الإعدادات!$H$8)) | AD59: =IF($B59="","",COUNTIF($C59:$X59,الإعدادات!$H$9)) | AE59: =IF($B59="","",COUNTIF($C59:$X59,الإعدادات!$H$10)) | AF59: =IF($B59="","",SUM(Y59:AC59))
...

Sheet شعبة 03
A1: =HYPERLINK("#'لوحة الشعب'!A1","⌂ "&IF('إعداد الشعب'!B6<>"نعم","صفحة غير مفعلة","سجل الفصل الأول – "&'إعداد الشعب'!C6&" – الصف "&'إعداد الشعب'!D6&" – شعبة "&'إعداد الشعب'!E6&" – "&IF('إعداد الشعب'!F6="",الإعدادات!B6,'إعداد الشعب'!F6))) -> ⌂ سجل الفصل الأول – إعدادية – الصف 7 – شعبة 3 – الحوسبة وتكنولوجيا المعلومات
A2: المرحلة | B2: ='إعداد الشعب'!C6 -> إعدادية | C2: الصف | D2: ='إعداد الشعب'!D6 -> 7 | E2: الشعبة | F2: ='إعداد الشعب'!E6 -> 3 | G2: المادة | H2: =IF('إعداد الشعب'!F6="",الإعدادات!B6,'إعداد الشعب'!F6) -> الحوسبة وتكنولوجيا المعلومات | I2: المعلم | J2: =IF('إعداد الشعب'!G6="",الإعدادات!B7,'إعداد الشعب'!G6) -> جمال صالح
A4: الطلاب | C4: الملاحظات | E4: الغياب | G4: النوم | I4: حل الواجبات | K4: تميز
A5: =COUNTIFS(B9:B48,"<>",C9:C48,"<>لا") -> 0 | C5: =SUM(AF53:AF92)+SUM(Z99:Z138)+SUM(AF145:AF184)+SUM(W191:W230) -> 0 | E5: =SUM(AB53:AB92)+SUM(V99:V138)+SUM(AB145:AB184)+SUM(S191:S230) -> 0 | G5: =SUM(Z53:Z92)+SUM(T99:T138)+SUM(Z145:Z184)+SUM(Q191:Q230) -> 0 | I5: =SUM(AD53:AD92)+SUM(X99:X138)+SUM(AD145:AD184)+SUM(U191:U230) -> 0 | K5: =SUM(AE53:AE92)+SUM(Y99:Y138)+SUM(AE145:AE184)+SUM(V191:V230) -> 0
A7: =HYPERLINK("#'شعبة 03'!A50","سبتمبر") -> سبتمبر | B7: =HYPERLINK("#'شعبة 03'!A96","أكتوبر") -> أكتوبر | C7: =HYPERLINK("#'شعبة 03'!A142","نوفمبر") -> نوفمبر | D7: =HYPERLINK("#'شعبة 03'!A188","ديسمبر") -> ديسمبر | E7: =HYPERLINK("#'لوحة الشعب'!A1","لوحة الشعب") -> لوحة الشعب
A8: م | B8: اسم الطالب | C8: نشط؟ | D8: ملاحظات | F8: تقرير سريع لطالب – الفصل الدراسي الأول
A9: 1 | F9: اختر الطالب
A10: 2 | F10: الخيار | G10: سبتمبر | H10: أكتوبر | I10: نوفمبر | J10: ديسمبر | K10: الإجمالي
A11: 3 | F11: =الإعدادات!H4 -> كتاب | G11: =IF($G$9="","",SUMIF($B$53:$B$92,$G$9,$Y$53:$Y$92)) | H11: =IF($G$9="","",SUMIF($B$99:$B$138,$G$9,$S$99:$S$138)) | I11: =IF($G$9="","",SUMIF($B$145:$B$184,$G$9,$Y$145:$Y$184)) | J11: =IF($G$9="","",SUMIF($B$191:$B$230,$G$9,$P$191:$P$230)) | K11: =SUM(G11:J11) -> 0
A12: 4 | F12: =الإعدادات!H5 -> نوم | G12: =IF($G$9="","",SUMIF($B$53:$B$92,$G$9,$Z$53:$Z$92)) | H12: =IF($G$9="","",SUMIF($B$99:$B$138,$G$9,$T$99:$T$138)) | I12: =IF($G$9="","",SUMIF($B$145:$B$184,$G$9,$Z$145:$Z$184)) | J12: =IF($G$9="","",SUMIF($B$191:$B$230,$G$9,$Q$191:$Q$230)) | K12: =SUM(G12:J12) -> 0
A13: 5 | F13: =الإعدادات!H6 -> سلوك | G13: =IF($G$9="","",SUMIF($B$53:$B$92,$G$9,$AA$53:$AA$92)) | H13: =IF($G$9="","",SUMIF($B$99:$B$138,$G$9,$U$99:$U$138)) | I13: =IF($G$9="","",SUMIF($B$145:$B$184,$G$9,$AA$145:$AA$184)) | J13: =IF($G$9="","",SUMIF($B$191:$B$230,$G$9,$R$191:$R$230)) | K13: =SUM(G13:J13) -> 0
A14: 6 | F14: =الإعدادات!H7 -> غياب | G14: =IF($G$9="","",SUMIF($B$53:$B$92,$G$9,$AB$53:$AB$92)) | H14: =IF($G$9="","",SUMIF($B$99:$B$138,$G$9,$V$99:$V$138)) | I14: =IF($G$9="","",SUMIF($B$145:$B$184,$G$9,$AB$145:$AB$184)) | J14: =IF($G$9="","",SUMIF($B$191:$B$230,$G$9,$S$191:$S$230)) | K14: =SUM(G14:J14) -> 0
A15: 7 | F15: =الإعدادات!H8 -> تأخر | G15: =IF($G$9="","",SUMIF($B$53:$B$92,$G$9,$AC$53:$AC$92)) | H15: =IF($G$9="","",SUMIF($B$99:$B$138,$G$9,$W$99:$W$138)) | I15: =IF($G$9="","",SUMIF($B$145:$B$184,$G$9,$AC$145:$AC$184)) | J15: =IF($G$9="","",SUMIF($B$191:$B$230,$G$9,$T$191:$T$230)) | K15: =SUM(G15:J15) -> 0
A16: 8 | F16: =الإعدادات!H9 -> حل الواجبات | G16: =IF($G$9="","",SUMIF($B$53:$B$92,$G$9,$AD$53:$AD$92)) | H16: =IF($G$9="","",SUMIF($B$99:$B$138,$G$9,$X$99:$X$138)) | I16: =IF($G$9="","",SUMIF($B$145:$B$184,$G$9,$AD$145:$AD$184)) | J16: =IF($G$9="","",SUMIF($B$191:$B$230,$G$9,$U$191:$U$230)) | K16: =SUM(G16:J16) -> 0
A17: 9 | F17: =الإعدادات!H10 -> تميز ★ | G17: =IF($G$9="","",SUMIF($B$53:$B$92,$G$9,$AE$53:$AE$92)) | H17: =IF($G$9="","",SUMIF($B$99:$B$138,$G$9,$Y$99:$Y$138)) | I17: =IF($G$9="","",SUMIF($B$145:$B$184,$G$9,$AE$145:$AE$184)) | J17: =IF($G$9="","",SUMIF($B$191:$B$230,$G$9,$V$191:$V$230)) | K17: =SUM(G17:J17) -> 0
A18: 10
A19: 11 | F19: الفصل الدراسي الأول: أدخل أسماء طلاب الشعبة أعلى الصفحة، ثم استخدم القوائم المنسدلة في سبتمبر–ديسمبر 2026. إجازة منتصف الفصل (25–29 أكتوبر) مستبعدة من التواريخ.
A20: 12
A21: 13
A22: 14
A23: 15
A24: 16
A25: 17
A26: 18
A27: 19
A28: 20
A29: 21
A30: 22
A31: 23
... A48: 40
A50: متابعة شهر سبتمبر 2026
A51: بيانات الطالب | C51: المتابعة اليومية | Y51: ملخص الشهر
A52: م | B52: اسم الطالب | C52: الثلاثاء 01/09 | D52: الأربعاء 02/09 | E52: الخميس 03/09 | F52: الأحد 06/09 | G52: الاثنين 07/09 | H52: الثلاثاء 08/09 | I52: الأربعاء 09/09 | J52: الخميس 10/09 | K52: الأحد 13/09 | L52: الاثنين 14/09 | M52: الثلاثاء 15/09 | N52: الأربعاء 16/09 | O52: الخميس 17/09 | P52: الأحد 20/09 | Q52: الاثنين 21/09 | R52: الثلاثاء 22/09 | S52: الأربعاء 23/09 | T52: الخميس 24/09 | U52: الأحد 27/09 | V52: الاثنين 28/09 | W52: الثلاثاء 29/09 | X52: الأربعاء 30/09 | Y52: =الإعدادات!H4 -> كتاب | Z52: =الإعدادات!H5 -> نوم | AA52: =الإعدادات!H6 -> سلوك | AB52: =الإعدادات!H7 -> غياب | AC52: =الإعدادات!H8 -> تأخر | AD52: =الإعدادات!H9 -> حل الواجبات | AE52: =الإعدادات!H10 -> تميز ★ | AF52: مجموع الملاحظات
A53: =IF(OR($B$9="",$C$9="لا"),"",$A$9) | B53: =IF(OR($B$9="",$C$9="لا"),"",$B$9) | Y53: =IF($B53="","",COUNTIF($C53:$X53,الإعدادات!$H$4)) | Z53: =IF($B53="","",COUNTIF($C53:$X53,الإعدادات!$H$5)) | AA53: =IF($B53="","",COUNTIF($C53:$X53,الإعدادات!$H$6)) | AB53: =IF($B53="","",COUNTIF($C53:$X53,الإعدادات!$H$7)) | AC53: =IF($B53="","",COUNTIF($C53:$X53,الإعدادات!$H$8)) | AD53: =IF($B53="","",COUNTIF($C53:$X53,الإعدادات!$H$9)) | AE53: =IF($B53="","",COUNTIF($C53:$X53,الإعدادات!$H$10)) | AF53: =IF($B53="","",SUM(Y53:AC53))
A54: =IF(OR($B$10="",$C$10="لا"),"",$A$10) | B54: =IF(OR($B$10="",$C$10="لا"),"",$B$10) | Y54: =IF($B54="","",COUNTIF($C54:$X54,الإعدادات!$H$4)) | Z54: =IF($B54="","",COUNTIF($C54:$X54,الإعدادات!$H$5)) | AA54: =IF($B54="","",COUNTIF($C54:$X54,الإعدادات!$H$6)) | AB54: =IF($B54="","",COUNTIF($C54:$X54,الإعدادات!$H$7)) | AC54: =IF($B54="","",COUNTIF($C54:$X54,الإعدادات!$H$8)) | AD54: =IF($B54="","",COUNTIF($C54:$X54,الإعدادات!$H$9)) | AE54: =IF($B54="","",COUNTIF($C54:$X54,الإعدادات!$H$10)) | AF54: =IF($B54="","",SUM(Y54:AC54))
A55: =IF(OR($B$11="",$C$11="لا"),"",$A$11) | B55: =IF(OR($B$11="",$C$11="لا"),"",$B$11) | Y55: =IF($B55="","",COUNTIF($C55:$X55,الإعدادات!$H$4)) | Z55: =IF($B55="","",COUNTIF($C55:$X55,الإعدادات!$H$5)) | AA55: =IF($B55="","",COUNTIF($C55:$X55,الإعدادات!$H$6)) | AB55: =IF($B55="","",COUNTIF($C55:$X55,الإعدادات!$H$7)) | AC55: =IF($B55="","",COUNTIF($C55:$X55,الإعدادات!$H$8)) | AD55: =IF($B55="","",COUNTIF($C55:$X55,الإعدادات!$H$9)) | AE55: =IF($B55="","",COUNTIF($C55:$X55,الإعدادات!$H$10)) | AF55: =IF($B55="","",SUM(Y55:AC55))
A56: =IF(OR($B$12="",$C$12="لا"),"",$A$12) | B56: =IF(OR($B$12="",$C$12="لا"),"",$B$12) | Y56: =IF($B56="","",COUNTIF($C56:$X56,الإعدادات!$H$4)) | Z56: =IF($B56="","",COUNTIF($C56:$X56,الإعدادات!$H$5)) | AA56: =IF($B56="","",COUNTIF($C56:$X56,الإعدادات!$H$6)) | AB56: =IF($B56="","",COUNTIF($C56:$X56,الإعدادات!$H$7)) | AC56: =IF($B56="","",COUNTIF($C56:$X56,الإعدادات!$H$8)) | AD56: =IF($B56="","",COUNTIF($C56:$X56,الإعدادات!$H$9)) | AE56: =IF($B56="","",COUNTIF($C56:$X56,الإعدادات!$H$10)) | AF56: =IF($B56="","",SUM(Y56:AC56))
A57: =IF(OR($B$13="",$C$13="لا"),"",$A$13) | B57: =IF(OR($B$13="",$C$13="لا"),"",$B$13) | Y57: =IF($B57="","",COUNTIF($C57:$X57,الإعدادات!$H$4)) | Z57: =IF($B57="","",COUNTIF($C57:$X57,الإعدادات!$H$5)) | AA57: =IF($B57="","",COUNTIF($C57:$X57,الإعدادات!$H$6)) | AB57: =IF($B57="","",COUNTIF($C57:$X57,الإعدادات!$H$7)) | AC57: =IF($B57="","",COUNTIF($C57:$X57,الإعدادات!$H$8)) | AD57: =IF($B57="","",COUNTIF($C57:$X57,الإعدادات!$H$9)) | AE57: =IF($B57="","",COUNTIF($C57:$X57,الإعدادات!$H$10)) | AF57: =IF($B57="","",SUM(Y57:AC57))
A58: =IF(OR($B$14="",$C$14="لا"),"",$A$14) | B58: =IF(OR($B$14="",$C$14="لا"),"",$B$14) | Y58: =IF($B58="","",COUNTIF($C58:$X58,الإعدادات!$H$4)) | Z58: =IF($B58="","",COUNTIF($C58:$X58,الإعدادات!$H$5)) | AA58: =IF($B58="","",COUNTIF($C58:$X58,الإعدادات!$H$6)) | AB58: =IF($B58="","",COUNTIF($C58:$X58,الإعدادات!$H$7)) | AC58: =IF($B58="","",COUNTIF($C58:$X58,الإعدادات!$H$8)) | AD58: =IF($B58="","",COUNTIF($C58:$X58,الإعدادات!$H$9)) | AE58: =IF($B58="","",COUNTIF($C58:$X58,الإعدادات!$H$10)) | AF58: =IF($B58="","",SUM(Y58:AC58))
A59: =IF(OR($B$15="",$C$15="لا"),"",$A$15) | B59: =IF(OR($B$15="",$C$15="لا"),"",$B$15) | Y59: =IF($B59="","",COUNTIF($C59:$X59,الإعدادات!$H$4)) | Z59: =IF($B59="","",COUNTIF($C59:$X59,الإعدادات!$H$5)) | AA59: =IF($B59="","",COUNTIF($C59:$X59,الإعدادات!$H$6)) | AB59: =IF($B59="","",COUNTIF($C59:$X59,الإعدادات!$H$7)) | AC59: =IF($B59="","",COUNTIF($C59:$X59,الإعدادات!$H$8)) | AD59: =IF($B59="","",COUNTIF($C59:$X59,الإعدادات!$H$9)) | AE59: =IF($B59="","",COUNTIF($C59:$X59,الإعدادات!$H$10)) | AF59: =IF($B59="","",SUM(Y59:AC59))
...

Sheet شعبة 04
A1: =HYPERLINK("#'لوحة الشعب'!A1","⌂ "&IF('إعداد الشعب'!B7<>"نعم","صفحة غير مفعلة","سجل الفصل الأول – "&'إعداد الشعب'!C7&" – الصف "&'إعداد الشعب'!D7&" – شعبة "&'إعداد الشعب'!E7&" – "&IF('إعداد الشعب'!F7="",الإعدادات!B6,'إعداد الشعب'!F7))) -> ⌂ سجل الفصل الأول – إعدادية – الصف 7 – شعبة 4 – الحوسبة وتكنولوجيا المعلومات
A2: المرحلة | B2: ='إعداد الشعب'!C7 -> إعدادية | C2: الصف | D2: ='إعداد الشعب'!D7 -> 7 | E2: الشعبة | F2: ='إعداد الشعب'!E7 -> 4 | G2: المادة | H2: =IF('إعداد الشعب'!F7="",الإعدادات!B6,'إعداد الشعب'!F7) -> الحوسبة وتكنولوجيا المعلومات | I2: المعلم | J2: =IF('إعداد الشعب'!G7="",الإعدادات!B7,'إعداد الشعب'!G7) -> جمال صالح
A4: الطلاب | C4: الملاحظات | E4: الغياب | G4: النوم | I4: حل الواجبات | K4: تميز
A5: =COUNTIFS(B9:B48,"<>",C9:C48,"<>لا") -> 0 | C5: =SUM(AF53:AF92)+SUM(Z99:Z138)+SUM(AF145:AF184)+SUM(W191:W230) -> 0 | E5: =SUM(AB53:AB92)+SUM(V99:V138)+SUM(AB145:AB184)+SUM(S191:S230) -> 0 | G5: =SUM(Z53:Z92)+SUM(T99:T138)+SUM(Z145:Z184)+SUM(Q191:Q230) -> 0 | I5: =SUM(AD53:AD92)+SUM(X99:X138)+SUM(AD145:AD184)+SUM(U191:U230) -> 0 | K5: =SUM(AE53:AE92)+SUM(Y99:Y138)+SUM(AE145:AE184)+SUM(V191:V230) -> 0
A7: =HYPERLINK("#'شعبة 04'!A50","سبتمبر") -> سبتمبر | B7: =HYPERLINK("#'شعبة 04'!A96","أكتوبر") -> أكتوبر | C7: =HYPERLINK("#'شعبة 04'!A142","نوفمبر") -> نوفمبر | D7: =HYPERLINK("#'شعبة 04'!A188","ديسمبر") -> ديسمبر | E7: =HYPERLINK("#'لوحة الشعب'!A1","لوحة الشعب") -> لوحة الشعب
A8: م | B8: اسم الطالب | C8: نشط؟ | D8: ملاحظات | F8: تقرير سريع لطالب – الفصل الدراسي الأول
A9: 1 | F9: اختر الطالب
A10: 2 | F10: الخيار | G10: سبتمبر | H10: أكتوبر | I10: نوفمبر | J10: ديسمبر | K10: الإجمالي
A11: 3 | F11: =الإعدادات!H4 -> كتاب | G11: =IF($G$9="","",SUMIF($B$53:$B$92,$G$9,$Y$53:$Y$92)) | H11: =IF($G$9="","",SUMIF($B$99:$B$138,$G$9,$S$99:$S$138)) | I11: =IF($G$9="","",SUMIF($B$145:$B$184,$G$9,$Y$145:$Y$184)) | J11: =IF($G$9="","",SUMIF($B$191:$B$230,$G$9,$P$191:$P$230)) | K11: =SUM(G11:J11) -> 0
A12: 4 | F12: =الإعدادات!H5 -> نوم | G12: =IF($G$9="","",SUMIF($B$53:$B$92,$G$9,$Z$53:$Z$92)) | H12: =IF($G$9="","",SUMIF($B$99:$B$138,$G$9,$T$99:$T$138)) | I12: =IF($G$9="","",SUMIF($B$145:$B$184,$G$9,$Z$145:$Z$184)) | J12: =IF($G$9="","",SUMIF($B$191:$B$230,$G$9,$Q$191:$Q$230)) | K12: =SUM(G12:J12) -> 0
A13: 5 | F13: =الإعدادات!H6 -> سلوك | G13: =IF($G$9="","",SUMIF($B$53:$B$92,$G$9,$AA$53:$AA$92)) | H13: =IF($G$9="","",SUMIF($B$99:$B$138,$G$9,$U$99:$U$138)) | I13: =IF($G$9="","",SUMIF($B$145:$B$184,$G$9,$AA$145:$AA$184)) | J13: =IF($G$9="","",SUMIF($B$191:$B$230,$G$9,$R$191:$R$230)) | K13: =SUM(G13:J13) -> 0
A14: 6 | F14: =الإعدادات!H7 -> غياب | G14: =IF($G$9="","",SUMIF($B$53:$B$92,$G$9,$AB$53:$AB$92)) | H14: =IF($G$9="","",SUMIF($B$99:$B$138,$G$9,$V$99:$V$138)) | I14: =IF($G$9="","",SUMIF($B$145:$B$184,$G$9,$AB$145:$AB$184)) | J14: =IF($G$9="","",SUMIF($B$191:$B$230,$G$9,$S$191:$S$230)) | K14: =SUM(G14:J14) -> 0
A15: 7 | F15: =الإعدادات!H8 -> تأخر | G15: =IF($G$9="","",SUMIF($B$53:$B$92,$G$9,$AC$53:$AC$92)) | H15: =IF($G$9="","",SUMIF($B$99:$B$138,$G$9,$W$99:$W$138)) | I15: =IF($G$9="","",SUMIF($B$145:$B$184,$G$9,$AC$145:$AC$184)) | J15: =IF($G$9="","",SUMIF($B$191:$B$230,$G$9,$T$191:$T$230)) | K15: =SUM(G15:J15) -> 0
A16: 8 | F16: =الإعدادات!H9 -> حل الواجبات | G16: =IF($G$9="","",SUMIF($B$53:$B$92,$G$9,$AD$53:$AD$92)) | H16: =IF($G$9="","",SUMIF($B$99:$B$138,$G$9,$X$99:$X$138)) | I16: =IF($G$9="","",SUMIF($B$145:$B$184,$G$9,$AD$145:$AD$184)) | J16: =IF($G$9="","",SUMIF($B$191:$B$230,$G$9,$U$191:$U$230)) | K16: =SUM(G16:J16) -> 0
A17: 9 | F17: =الإعدادات!H10 -> تميز ★ | G17: =IF($G$9="","",SUMIF($B$53:$B$92,$G$9,$AE$53:$AE$92)) | H17: =IF($G$9="","",SUMIF($B$99:$B$138,$G$9,$Y$99:$Y$138)) | I17: =IF($G$9="","",SUMIF($B$145:$B$184,$G$9,$AE$145:$AE$184)) | J17: =IF($G$9="","",SUMIF($B$191:$B$230,$G$9,$V$191:$V$230)) | K17: =SUM(G17:J17) -> 0
A18: 10
A19: 11 | F19: الفصل الدراسي الأول: أدخل أسماء طلاب الشعبة أعلى الصفحة، ثم استخدم القوائم المنسدلة في سبتمبر–ديسمبر 2026. إجازة منتصف الفصل (25–29 أكتوبر) مستبعدة من التواريخ.
A20: 12
A21: 13
A22: 14
A23: 15
A24: 16
A25: 17
A26: 18
A27: 19
A28: 20
A29: 21
A30: 22
A31: 23
... A48: 40
A50: متابعة شهر سبتمبر 2026
A51: بيانات الطالب | C51: المتابعة اليومية | Y51: ملخص الشهر
A52: م | B52: اسم الطالب | C52: الثلاثاء 01/09 | D52: الأربعاء 02/09 | E52: الخميس 03/09 | F52: الأحد 06/09 | G52: الاثنين 07/09 | H52: الثلاثاء 08/09 | I52: الأربعاء 09/09 | J52: الخميس 10/09 | K52: الأحد 13/09 | L52: الاثنين 14/09 | M52: الثلاثاء 15/09 | N52: الأربعاء 16/09 | O52: الخميس 17/09 | P52: الأحد 20/09 | Q52: الاثنين 21/09 | R52: الثلاثاء 22/09 | S52: الأربعاء 23/09 | T52: الخميس 24/09 | U52: الأحد 27/09 | V52: الاثنين 28/09 | W52: الثلاثاء 29/09 | X52: الأربعاء 30/09 | Y52: =الإعدادات!H4 -> كتاب | Z52: =الإعدادات!H5 -> نوم | AA52: =الإعدادات!H6 -> سلوك | AB52: =الإعدادات!H7 -> غياب | AC52: =الإعدادات!H8 -> تأخر | AD52: =الإعدادات!H9 -> حل الواجبات | AE52: =الإعدادات!H10 -> تميز ★ | AF52: مجموع الملاحظات
A53: =IF(OR($B$9="",$C$9="لا"),"",$A$9) | B53: =IF(OR($B$9="",$C$9="لا"),"",$B$9) | O53: كتاب | Y53: =IF($B53="","",COUNTIF($C53:$X53,الإعدادات!$H$4)) | Z53: =IF($B53="","",COUNTIF($C53:$X53,الإعدادات!$H$5)) | AA53: =IF($B53="","",COUNTIF($C53:$X53,الإعدادات!$H$6)) | AB53: =IF($B53="","",COUNTIF($C53:$X53,الإعدادات!$H$7)) | AC53: =IF($B53="","",COUNTIF($C53:$X53,الإعدادات!$H$8)) | AD53: =IF($B53="","",COUNTIF($C53:$X53,الإعدادات!$H$9)) | AE53: =IF($B53="","",COUNTIF($C53:$X53,الإعدادات!$H$10)) | AF53: =IF($B53="","",SUM(Y53:AC53))
A54: =IF(OR($B$10="",$C$10="لا"),"",$A$10) | B54: =IF(OR($B$10="",$C$10="لا"),"",$B$10) | O54: كتاب | Q54: تميز ★ | Y54: =IF($B54="","",COUNTIF($C54:$X54,الإعدادات!$H$4)) | Z54: =IF($B54="","",COUNTIF($C54:$X54,الإعدادات!$H$5)) | AA54: =IF($B54="","",COUNTIF($C54:$X54,الإعدادات!$H$6)) | AB54: =IF($B54="","",COUNTIF($C54:$X54,الإعدادات!$H$7)) | AC54: =IF($B54="","",COUNTIF($C54:$X54,الإعدادات!$H$8)) | AD54: =IF($B54="","",COUNTIF($C54:$X54,الإعدادات!$H$9)) | AE54: =IF($B54="","",COUNTIF($C54:$X54,الإعدادات!$H$10)) | AF54: =IF($B54="","",SUM(Y54:AC54))
A55: =IF(OR($B$11="",$C$11="لا"),"",$A$11) | B55: =IF(OR($B$11="",$C$11="لا"),"",$B$11) | Y55: =IF($B55="","",COUNTIF($C55:$X55,الإعدادات!$H$4)) | Z55: =IF($B55="","",COUNTIF($C55:$X55,الإعدادات!$H$5)) | AA55: =IF($B55="","",COUNTIF($C55:$X55,الإعدادات!$H$6)) | AB55: =IF($B55="","",COUNTIF($C55:$X55,الإعدادات!$H$7)) | AC55: =IF($B55="","",COUNTIF($C55:$X55,الإعدادات!$H$8)) | AD55: =IF($B55="","",COUNTIF($C55:$X55,الإعدادات!$H$9)) | AE55: =IF($B55="","",COUNTIF($C55:$X55,الإعدادات!$H$10)) | AF55: =IF($B55="","",SUM(Y55:AC55))
